Workbook

Sheet สรุป 1 ธค 68
A1: สถานะผู้ยี่นขอขนานไฟกับ PEA บนระบบ PPIM ของ กฟฟ. จุดรวมงาน (กรณีไม่เกิน 20 kW) (ราย)
B2: รอตรวจสอบแบบคำขอ | C2: ยกเลิก | D2: รอผู้ยื่นคำขอส่งเอกสารแก้ไข | E2: รอชำระเงิน | F2: รออนุมัติเชื่อมต่อ/รับพิจารณา | G2: รอดำเนินการหลังอนุมัติเชื่อมต่อ/รับพิจารณา | H2: รอแก้ไขเอกสารหลังอนุมัติเชื่อมต่อ / รับพิจารณา | I2: รอตรวจสอบระบบผลิต | J2: รอทดสอบเชื่อมต่อ | K2: รออนุมัติแจ้งวันเริ่มเชื่อมต่อ | L2: เชื่อมต่อเรียบร้อยแล้ว | M2: รวม | O2: รอตรวจสอบเอกสาร | P2: รอแจ้งแก้ไขเอกสาร | Q2: แจ้งแก้ไขเอกสารแล้วเสร็จ | R2: รอใบอนุญาต | T2: บริษัทแก้ไขเอกสารแล้วเสร็จ | U2: รอแจ้งค่าใช้จ่าย | V2: รอชำระค่าใช้จ่าย | W2: รอทดสอบ Relay | X2: รอเปลี่ยนมิเตอร์กันถอย | Y2: รอรายงานการติดตั้ง | Z2: รอนัดทดสอบ First Sync | AA2: รอแก้ไขหลังทดสอบ First Sync
A3: กฟส.เมืองนครปฐม | B3: ='กฟจ นฐ'!M3 -> 0 | C3: ='กฟจ นฐ'!M4 -> 50 | D3: ='กฟจ นฐ'!M5 -> 2 | E3: ='กฟจ นฐ'!M6 -> 44 | F3: ='กฟจ นฐ'!M7 -> 2 | G3: ='กฟจ นฐ'!M8 -> 17 | H3: ='กฟจ นฐ'!M9 -> 1 | I3: ='กฟจ นฐ'!M11 -> 2 | J3: ='กฟจ นฐ'!M12 -> 0 | K3: ='กฟจ นฐ'!M13 -> 0 | L3: ='กฟจ นฐ'!M14 -> 132 | M3: =SUM(B3:L3) -> 250
A4: กฟส.นครชัยศรี | B4: ='กฟส นครชัยศรี'!M3 -> 10 | C4: ='กฟส นครชัยศรี'!M4 -> 58 | D4: ='กฟส นครชัยศรี'!M5 -> 0 | E4: ='กฟส นครชัยศรี'!M6 -> 2 | F4: ='กฟส นครชัยศรี'!M7 -> 4 | G4: ='กฟส นครชัยศรี'!M8 -> 2 | H4: ='กฟส นครชัยศรี'!M9 -> 0 | I4: ='กฟส นครชัยศรี'!M11 -> 1 | J4: ='กฟส นครชัยศรี'!M12 -> 0 | K4: ='กฟส นครชัยศรี'!M13 -> 0 | L4: ='กฟส นครชัยศรี'!M14 -> 25 | M4: =SUM(B4:L4) -> 102
A5: กฟส กำแพงแสน | B5: ='กฟส กำแพงแสน'!M3 -> 2 | C5: ='กฟส กำแพงแสน'!M4 -> 44 | D5: ='กฟส กำแพงแสน'!M5 -> 1 | E5: ='กฟส กำแพงแสน'!M6 -> 3 | F5: ='กฟส กำแพงแสน'!M7 -> 1 | G5: ='กฟส กำแพงแสน'!M8 -> 7 | H5: ='กฟส กำแพงแสน'!M9 -> 1 | I5: ='กฟส กำแพงแสน'!M11 -> 1 | J5: ='กฟส กำแพงแสน'!M12 -> 0 | K5: ='กฟส กำแพงแสน'!M13 -> 0 | L5: ='กฟส กำแพงแสน'!M14 -> 26 | M5: =SUM(B5:L5) -> 86
A6: กฟส สามพราน | B6: ='กฟส สามพราน'!M3 -> 24 | C6: ='กฟส สามพราน'!M4 -> 214 | D6: ='กฟส สามพราน'!M5 -> 0 | E6: ='กฟส สามพราน'!M6 -> 2 | F6: ='กฟส สามพราน'!M7 -> 0 | G6: ='กฟส สามพราน'!M8 -> 4 | H6: ='กฟส สามพราน'!M9 -> 3 | I6: ='กฟส สามพราน'!M11 -> 2 | J6: ='กฟส สามพราน'!M12 -> 0 | K6: ='กฟส สามพราน'!M13 -> 0 | L6: ='กฟส สามพราน'!M14 -> 44 | M6: =SUM(B6:L6) -> 293
A7: กฟส บางเลน | B7: ='กฟส บางเลน'!M3 -> 14 | C7: ='กฟส บางเลน'!M4 -> 8 | D7: ='กฟส บางเลน'!M5 -> 0 | E7: ='กฟส บางเลน'!M6 -> 1 | F7: ='กฟส บางเลน'!M7 -> 13 | G7: ='กฟส บางเลน'!M8 -> 3 | H7: ='กฟส บางเลน'!M9 -> 0 | I7: ='กฟส บางเลน'!M11 -> 8 | J7: ='กฟส บางเลน'!M12 -> 0 | K7: ='กฟส บางเลน'!M13 -> 0 | L7: ='กฟส บางเลน'!M14 -> 5 | M7: =SUM(B7:L7) -> 52
A8: กฟส พุทธมณฑล | B8: ='กฟส พุทธมณฑล'!M3 -> 20 | C8: ='กฟส พุทธมณฑล'!M4 -> 35 | D8: ='กฟส พุทธมณฑล'!M5 -> 0 | E8: ='กฟส พุทธมณฑล'!M6 -> 0 | F8: ='กฟส พุทธมณฑล'!M7 -> 3 | G8: ='กฟส พุทธมณฑล'!M8 -> 9 | H8: ='กฟส พุทธมณฑล'!M9 -> 0 | I8: ='กฟส พุทธมณฑล'!M11 -> 0 | J8: ='กฟส พุทธมณฑล'!M12 -> 0 | K8: ='กฟส พุทธมณฑล'!M13 -> 0 | L8: ='กฟส พุทธมณฑล'!M14 -> 34 | M8: =SUM(B8:L8) -> 101
A9: รวมสังกัด กฟฟ จ.นครปฐม | B9: =SUM(B3:B8) -> 70 | C9: =SUM(C3:C8) -> 409 | D9: =SUM(D3:D8) -> 3 | E9: =SUM(E3:E8) -> 52 | F9: =SUM(F3:F8) -> 23 | G9: =SUM(G3:G8) -> 42 | H9: =SUM(H3:H8) -> 5 | I9: =SUM(I3:I8) -> 14 | ... L9: =SUM(L3:L8) -> 266 | M9: =SUM(B9:L9) -> 884 | N9: =SUM(M3:M8) -> 884
B10: รอตรวจสอบแบบคำขอ | C10: ยกเลิก | D10: รอผู้ยื่นคำขอส่งเอกสารแก้ไข | E10: รอชำระเงิน | F10: รออนุมัติเชื่อมต่อ/รับพิจารณา | G10: รอดำเนินการหลังอนุมัติเชื่อมต่อ/รับพิจารณา | H10: รอแก้ไขเอกสารหลังอนุมัติเชื่อมต่อ / รับพิจารณา | I10: รอตรวจสอบระบบผลิต | J10: รอทดสอบเชื่อมต่อ | K10: รออนุมัติแจ้งวันเริ่มเชื่อมต่อ | L10: เชื่อมต่อเรียบร้อยแล้ว | M10: รวม
A11: กฟส.เมืองสมุทรสาคร | B11: ='กฟจ สค'!M3 -> 4 | C11: ='กฟจ สค'!M4 -> 50 | D11: ='กฟจ สค'!M5 -> 1 | E11: ='กฟจ สค'!M6 -> 12 | F11: ='กฟจ สค'!M7 -> 3 | G11: ='กฟจ สค'!M8 -> 6 | H11: ='กฟจ สค'!M9 -> 4 | I11: ='กฟจ สค'!M11 -> 17 | J11: ='กฟจ สค'!M12 -> 0 | K11: ='กฟจ สค'!M13 -> 6 | L11: ='กฟจ สค'!M14 -> 103 | M11: =SUM(B11:L11) -> 206
A12: กฟส.อ้อมน้อย | B12: ='กฟส อ้อมน้อย'!M3 -> 8 | C12: ='กฟส อ้อมน้อย'!M4 -> 284 | D12: ='กฟส อ้อมน้อย'!M5 -> 0 | E12: ='กฟส อ้อมน้อย'!M6 -> 3 | F12: ='กฟส อ้อมน้อย'!M7 -> 0 | G12: ='กฟส อ้อมน้อย'!M8 -> 5 | H12: ='กฟส อ้อมน้อย'!M9 -> 3 | I12: ='กฟส อ้อมน้อย'!M11 -> 1 | J12: ='กฟส อ้อมน้อย'!M12 -> 0 | K12: ='กฟส อ้อมน้อย'!M13 -> 0 | L12: ='กฟส อ้อมน้อย'!M14 -> 24 | M12: =SUM(B12:L12) -> 328
A13: กฟส.กระทุ่มแบน | B13: ='กฟส กระทุ่มแบน'!M3 -> 7 | C13: ='กฟส กระทุ่มแบน'!M4 -> 11 | D13: ='กฟส กระทุ่มแบน'!M5 -> 0 | E13: ='กฟส กระทุ่มแบน'!M6 -> 10 | F13: ='กฟส กระทุ่มแบน'!M7 -> 1 | G13: ='กฟส กระทุ่มแบน'!M8 -> 9 | H13: ='กฟส กระทุ่มแบน'!M9 -> 0 | I13: ='กฟส กระทุ่มแบน'!M11 -> 6 | J13: ='กฟส กระทุ่มแบน'!M12 -> 0 | K13: ='กฟส กระทุ่มแบน'!M13 -> 0 | L13: ='กฟส กระทุ่มแบน'!M14 -> 23 | M13: =SUM(B13:L13) -> 67
A14: กฟส.สมุทรสาคร 2 | B14: ='กฟส สมุทรสาคร 2'!M3 -> 0 | C14: ='กฟส สมุทรสาคร 2'!M4 -> 19 | D14: ='กฟส สมุทรสาคร 2'!M5 -> 0 | E14: ='กฟส สมุทรสาคร 2'!M6 -> 6 | F14: ='กฟส สมุทรสาคร 2'!M7 -> 0 | G14: ='กฟส สมุทรสาคร 2'!M8 -> 4 | H14: ='กฟส สมุทรสาคร 2'!M9 -> 0 | I14: ='กฟส สมุทรสาคร 2'!M11 -> 0 | J14: ='กฟส สมุทรสาคร 2'!M12 -> 0 | K14: ='กฟส สมุทรสาคร 2'!M13 -> 0 | L14: ='กฟส สมุทรสาคร 2'!M14 -> 24 | M14: =SUM(B14:L14) -> 53
A15: กฟส.โคกขาม | B15: ='กฟส โคกขาม'!M3 -> 2 | C15: ='กฟส โคกขาม'!M4 -> 21 | D15: ='กฟส โคกขาม'!M5 -> 0 | E15: ='กฟส โคกขาม'!M6 -> 5 | F15: ='กฟส โคกขาม'!M7 -> 0 | G15: ='กฟส โคกขาม'!M8 -> 7 | H15: ='กฟส โคกขาม'!M9 -> 0 | I15: ='กฟส โคกขาม'!M11 -> 3 | J15: ='กฟส โคกขาม'!M12 -> 0 | K15: ='กฟส โคกขาม'!M13 -> 0 | L15: ='กฟส โคกขาม'!M14 -> 72 | M15: =SUM(B15:L15) -> 110
A16: รวม สังกัด กฟฟ จ..สมุทรสาคร | B16: =SUM(B11:B15) -> 21 | C16: =SUM(C11:C15) -> 385 | D16: =SUM(D11:D15) -> 1 | E16: =SUM(E11:E15) -> 36 | F16: =SUM(F11:F15) -> 4 | G16: =SUM(G11:G15) -> 31 | H16: =SUM(H11:H15) -> 7 | I16: =SUM(I11:I15) -> 27 | ... L16: =SUM(L11:L15) -> 246 | M16: =SUM(B16:L16) -> 764 | N16: =SUM(M11:M15) -> 764
B17: รอตรวจสอบแบบคำขอ | C17: ยกเลิก | D17: รอผู้ยื่นคำขอส่งเอกสารแก้ไข | E17: รอชำระเงิน | F17: รออนุมัติเชื่อมต่อ/รับพิจารณา | G17: รอดำเนินการหลังอนุมัติเชื่อมต่อ/รับพิจารณา | H17: รอแก้ไขเอกสารหลังอนุมัติเชื่อมต่อ / รับพิจารณา | I17: รอตรวจสอบระบบผลิต | J17: รอทดสอบเชื่อมต่อ | K17: รออนุมัติแจ้งวันเริ่มเชื่อมต่อ | L17: เชื่อมต่อเรียบร้อยแล้ว | M17: รวม
A18: กฟส.เมืองกาญจนบุรี | B18: ='กฟจ กจ'!M3 -> 0 | C18: ='กฟจ กจ'!M4 -> 146 | D18: ='กฟจ กจ'!M5 -> 0 | E18: ='กฟจ กจ'!M6 -> 16 | F18: ='กฟจ กจ'!M7 -> 2 | G18: ='กฟจ กจ'!M8 -> 14 | H18: ='กฟจ กจ'!M9 -> 2 | I18: ='กฟจ กจ'!M11 -> 0 | J18: ='กฟจ กจ'!M12 -> 0 | K18: ='กฟจ กจ'!M13 -> 0 | L18: ='กฟจ กจ'!M14 -> 114 | M18: =SUM(B18:L18) -> 294
A19: กฟส.บ่อพลอย | B19: ='กฟส บ่อพลอย'!M3 -> 1 | C19: ='กฟส บ่อพลอย'!M4 -> 25 | D19: ='กฟส บ่อพลอย'!M5 -> 0 | E19: ='กฟส บ่อพลอย'!M6 -> 0 | F19: ='กฟส บ่อพลอย'!M7 -> 0 | G19: ='กฟส บ่อพลอย'!M8 -> 3 | H19: ='กฟส บ่อพลอย'!M9 -> 1 | I19: ='กฟส บ่อพลอย'!M11 -> 1 | J19: ='กฟส บ่อพลอย'!M12 -> 0 | K19: ='กฟส บ่อพลอย'!M13 -> 0 | L19: ='กฟส บ่อพลอย'!M14 -> 23 | M19: =SUM(B19:L19) -> 54
A20: กฟส.ท่ามะกา | B20: ='กฟส ท่ามะกา'!M3 -> 4 | C20: ='กฟส ท่ามะกา'!M4 -> 39 | D20: ='กฟส ท่ามะกา'!M5 -> 2 | E20: ='กฟส ท่ามะกา'!M6 -> 1 | F20: ='กฟส ท่ามะกา'!M7 -> 2 | G20: ='กฟส ท่ามะกา'!M8 -> 2 | H20: ='กฟส ท่ามะกา'!M9 -> 0 | I20: ='กฟส ท่ามะกา'!M11 -> 7 | J20: ='กฟส ท่ามะกา'!M12 -> 0 | K20: ='กฟส ท่ามะกา'!M13 -> 0 | L20: ='กฟส ท่ามะกา'!M14 -> 18 | M20: =SUM(B20:L20) -> 75 | T20: พื้นที่ | U20: เชื่อมต่อแล้ว | V20: ยังไม่เชื่อมต่อ | W20: รวม (MW) | X20: %
A21: รวม สังกัด กฟฟ จ.กาญจนบุรี | B21: =SUM(B18:B20) -> 5 | C21: =SUM(C18:C20) -> 210 | D21: =SUM(D18:D20) -> 2 | E21: =SUM(E18:E20) -> 17 | F21: =SUM(F18:F20) -> 4 | G21: =SUM(G18:G20) -> 19 | H21: =SUM(H18:H20) -> 3 | I21: =SUM(I18:I20) -> 8 | ... L21: =SUM(L18:L20) -> 155 | M21: =SUM(B21:L21) -> 423 | T21: สนญ. | U21: 3 | V21: 389 | W21: 392 | X21: =U21/W21*100 -> 0.76530612 | Y21: =_xlfn.RANK.AVG(X21,X$21:X$34) -> 13
B22: รอตรวจสอบแบบคำขอ | C22: ยกเลิก | D22: รอผู้ยื่นคำขอส่งเอกสารแก้ไข | E22: รอชำระเงิน | F22: รออนุมัติเชื่อมต่อ/รับพิจารณา | G22: รอดำเนินการหลังอนุมัติเชื่อมต่อ/รับพิจารณา | H22: รอแก้ไขเอกสารหลังอนุมัติเชื่อมต่อ / รับพิจารณา | I22: รอตรวจสอบระบบผลิต | J22: รอทดสอบเชื่อมต่อ | K22: รออนุมัติแจ้งวันเริ่มเชื่อมต่อ | L22: เชื่อมต่อเรียบร้อยแล้ว | M22: รวม | T22: น.1 | U22: 710 | V22: 695 | W22: 1405 | X22: =U22/W22*100 -> 50.533808 | Y22: =_xlfn.RANK.AVG(X22,X$21:X$34) -> 2
A23: กฟส.เมืองสุพรรณบุรี | B23: ='กฟจ สพ'!M3 -> 9 | C23: ='กฟจ สพ'!M4 -> 57 | D23: ='กฟจ สพ'!M5 -> 0 | E23: ='กฟจ สพ'!M6 -> 31 | F23: ='กฟจ สพ'!M7 -> 1 | G23: ='กฟจ สพ'!M8 -> 29 | H23: ='กฟจ สพ'!M9 -> 0 | I23: ='กฟจ สพ'!M11 -> 3 | J23: ='กฟจ สพ'!M12 -> 0 | K23: ='กฟจ สพ'!M13 -> 0 | L23: ='กฟจ สพ'!M14 -> 87 | M23: =SUM(B23:L23) -> 217 | T23: น.2 | U23: 196 | V23: 836 | W23: 1032 | X23: =U23/W23*100 -> 18.992248 | Y23: =_xlfn.RANK.AVG(X23,X$21:X$34) -> 12
A24: กฟอ.อู่ทอง | B24: ='กฟอ อู่ทอง'!M3 -> 6 | C24: ='กฟอ อู่ทอง'!M4 -> 43 | D24: ='กฟอ อู่ทอง'!M5 -> 0 | E24: ='กฟอ อู่ทอง'!M6 -> 4 | F24: ='กฟอ อู่ทอง'!M7 -> 13 | G24: ='กฟอ อู่ทอง'!M8 -> 14 | H24: ='กฟอ อู่ทอง'!M9 -> 0 | I24: ='กฟอ อู่ทอง'!M11 -> 7 | J24: ='กฟอ อู่ทอง'!M12 -> 0 | K24: ='กฟอ อู่ทอง'!M13 -> 0 | L24: ='กฟอ อู่ทอง'!M14 -> 25 | M24: =SUM(B24:L24) -> 112 | T24: น.3 | U24: 219 | V24: 432 | W24: 651 | X24: =U24/W24*100 -> 33.640553 | Y24: =_xlfn.RANK.AVG(X24,X$21:X$34) -> 7
A25: กฟอ.เดิมบาง | B25: ='กฟส เดิมบาง'!M3 -> 0 | C25: ='กฟส เดิมบาง'!M4 -> 38 | D25: ='กฟส เดิมบาง'!M5 -> 1 | E25: ='กฟส เดิมบาง'!M6 -> 3 | F25: ='กฟส เดิมบาง'!M7 -> 1 | G25: ='กฟส เดิมบาง'!M8 -> 8 | H25: ='กฟส เดิมบาง'!M9 -> 0 | I25: ='กฟส เดิมบาง'!M11 -> 0 | J25: ='กฟส เดิมบาง'!M12 -> 0 | K25: ='กฟส เดิมบาง'!M13 -> 1 | L25: ='กฟส เดิมบาง'!M14 -> 28 | M25: =SUM(B25:L25) -> 80 | T25: ฉ.1 | U25: 277 | V25: 671 | W25: 948 | X25: =U25/W25*100 -> 29.219409 | Y25: =_xlfn.RANK.AVG(X25,X$21:X$34) -> 8
A26: รวม สังกัด กฟฟ จ.สุพรรณบุรี | B26: =SUM(B23:B25) -> 15 | C26: =SUM(C23:C25) -> 138 | D26: =SUM(D23:D25) -> 1 | E26: =SUM(E23:E25) -> 38 | F26: =SUM(F23:F25) -> 15 | G26: =SUM(G23:G25) -> 51 | H26: =SUM(H23:H25) -> 0 | I26: =SUM(I23:I25) -> 10 | ... L26: =SUM(L23:L25) -> 140 | M26: =SUM(B26:L26) -> 409 | T26: ฉ.2 | U26: 233 | V26: 691 | W26: 924 | X26: =U26/W26*100 -> 25.21645 | Y26: =_xlfn.RANK.AVG(X26,X$21:X$34) -> 11
B27: รอตรวจสอบแบบคำขอ | C27: ยกเลิก | D27: รอผู้ยื่นคำขอส่งเอกสารแก้ไข | E27: รอชำระเงิน | F27: รออนุมัติเชื่อมต่อ/รับพิจารณา | G27: รอดำเนินการหลังอนุมัติเชื่อมต่อ/รับพิจารณา | H27: รอแก้ไขเอกสารหลังอนุมัติเชื่อมต่อ / รับพิจารณา | I27: รอตรวจสอบระบบผลิต | J27: รอทดสอบเชื่อมต่อ | K27: รออนุมัติแจ้งวันเริ่มเชื่อมต่อ | L27: เชื่อมต่อเรียบร้อยแล้ว | M27: รวม | T27: ฉ.3 | U27: 613 | V27: 410 | W27: 1023 | X27: =U27/W27*100 -> 59.921799 | Y27: =_xlfn.RANK.AVG(X27,X$21:X$34) -> 1
A28: รวม กฟฟ | B28: =B9+B16+B21+B26 -> 111 | C28: =C9+C16+C21+C26 -> 1142 | D28: =D9+D16+D21+D26 -> 7 | E28: =E9+E16+E21+E26 -> 143 | F28: =F9+F16+F21+F26 -> 46 | G28: =G9+G16+G21+G26 -> 143 | H28: =H9+H16+H21+H26 -> 15 | I28: =I9+I16+I21+I26 -> 59 | ... M28: =M9+M16+M21+M26 -> 2480 | T28: ก.1 | U28: 593 | V28: 1652 | W28: 2245 | X28: =U28/W28*100 -> 26.414254 | Y28: =_xlfn.RANK.AVG(X28,X$21:X$34) -> 10
B29: รอตรวจสอบแบบคำขอ | C29: ยกเลิก | D29: รอผู้ยื่นคำขอส่งเอกสารแก้ไข | E29: รอชำระเงิน | F29: รออนุมัติเชื่อมต่อ/รับพิจารณา | G29: รอดำเนินการหลังอนุมัติเชื่อมต่อ/รับพิจารณา | H29: รอแก้ไขเอกสารหลังอนุมัติเชื่อมต่อ / รับพิจารณา | I29: รออนุมัติเชื่อมต่อ (200 kW ขึ้นไป) | J29: รอตรวจสอบระบบผลิต | K29: รอทดสอบเชื่อมต่อ | L29: รออนุมัติแจ้งวันเริ่มเชื่อมต่อ | M29: เชื่อมต่อเรียบร้อยแล้ว | N29: รวม | O29: เว้นยกเลิก | P29: % เชื่อมต่อแล้วเสร็จ | T29: ก.2 | U29: 814 | V29: 1404 | W29: 2218 | X29: =U29/W29*100 -> 36.699729 | Y29: =_xlfn.RANK.AVG(X29,X$21:X$34) -> 5
A30: กวว. | B30: =กวว.!M3 -> 71 | C30: =กวว.!M4 -> 1778 | D30: =กวว.!M5 -> 18 | E30: =กวว.!M6 -> 96 | F30: =กวว.!M7 -> 0 | G30: =กวว.!M8 -> 73 | H30: =กวว.!M9 -> 79 | I30: =กวว.!M10 -> 0 | J30: =กวว.!M11 -> 259 | K30: =กวว.!M12 -> 7 | L30: =กวว.!M13 -> 0 | M30: =กวว.!M14 -> 301 | N30: =SUM(B30:M30) -> 2682 | O30: =N30-C30 -> 904 | P30: =M30/O30*100 -> 33.29646 | T30: ก.3 | U30: 537 | V30: 948 | W30: 1485 | X30: =U30/W30*100 -> 36.161616 | Y30: =_xlfn.RANK.AVG(X30,X$21:X$34) -> 6
T31: ต.1 | U31: 338 | V31: 363 | W31: 701 | X31: =U31/W31*100 -> 48.216833 | Y31: =_xlfn.RANK.AVG(X31,X$21:X$34) -> 3
T32: ต.2 | U32: 184 | V32: 453 | W32: 637 | X32: =U32/W32*100 -> 28.8854 | Y32: =_xlfn.RANK.AVG(X32,X$21:X$34) -> 9
T33: ต.3 | U33: 154 | V33: 252 | W33: 406 | X33: =U33/W33*100 -> 37.931034 | Y33: =_xlfn.RANK.AVG(X33,X$21:X$34) -> 4
T34: n/a | U34: 0 | V34: 11 | W34: 11 | X34: =U34/W34*100 -> 0 | Y34: =_xlfn.RANK.AVG(X34,X$21:X$34) -> 14

Sheet กวว.
A1: เลขที่คำขอ | B1: หมายเลข CA | C1: ชื่อผู้ใช้ไฟฟ้า | D1: วันที่ยื่นคำขอ | E1: วันที่ยื่นแก้ไขคำขอ | F1: กำลังการผลิต (kW) | G1: วันที่ชำระเงิน | H1: สถานะคำขอ | J1: พื้นที่ กฟฟ.
A2: PPIM18500014 | B2: 20025324026 | C2: นายณัฐพล ลีลากนก | D2: 45306.672 | E2: - | F2: 40 | G2: - | H2: ยกเลิก | I2: - | J2: กฟก.3 | L2: รวม | M2: =COUNT(B:B) -> 2682 | N2: ราย
A3: PPIM18500045 | B3: 20022269044 | C3: ชัยณรงค์ ภู่วาว | D3: 45308.427 | E3: - | F3: 30 | G3: - | H3: ยกเลิก | I3: - | J3: กฟก.3 | L3: รอตรวจสอบคำขอ | M3: =COUNTIF(H:H,"รอตรวจสอบคำขอ") -> 71 | N3: ราย
A4: PPIM1850005F | B4: 20018950093 | C4: บริษัท ที.ซี. ยูเนียน อโกรเทค จำกัด | D4: 45308.674 | E4: - | F4: 180 | G4: - | H4: ยกเลิก | I4: - | J4: กฟก.3 | L4: ยกเลิก | M4: =COUNTIF(H:H,"ยกเลิก") -> 1778 | N4: ราย
A5: PPIM18500076 | B5: 20022056496 | C5: บริษัท ปตท. น้ำมันและการค้าปลีก จำกัด (มหาชน) | D5: 45309.58 | E5: - | F5: 20 | G5: - | H5: ยกเลิก | I5: - | J5: กฟก.3 | L5: รอผู้ยื่นคำขอส่งเอกสารแก้ไข | M5: =COUNTIF(H:H,"รอผู้ยื่นคำขอส่งเอกสารแก้ไข") -> 18 | N5: ราย
A6: PPIM185000C0 | B6: 20021080228 | C6: นายปิยะมิตร ศรีสว่าง | D6: 45313.462 | E6: - | F6: 30 | G6: - | H6: ยกเลิก | I6: - | J6: กฟก.3 | L6: รอชำระเงิน | M6: =COUNTIF(H:H,"รอชำระเงิน") -> 96 | N6: ราย | O6: (รวม รอ หผ / อก / ผจก อนุมัติ ด้วย)
A7: PPIM185000D8 | B7: 20017188779 | C7: นาย เอกพจน์ เกิดดอนแฝก | D7: 45313.824 | E7: - | F7: 100 | G7: - | H7: ยกเลิก | I7: - | J7: กฟก.3 | L7: รออนุมัติเชื่อมต่อ/รับพิจารณา | M7: =COUNTIF(H:H,"รออนุมัติเชื่อมต่อ/รับพิจารณา")+COUNTIF(H:H,"รอ หผ. อนุมัติ")+COUNTIF(H:H,"รอ ผจก./อก. อนุมัติ") -> 0 | N7: ราย
A8: PPIM185000FF | B8: 20003142103 | C8: บริษัท สยามฟริท จำกัด | D8: 45314.624 | E8: - | F8: 175 | G8: - | H8: ยกเลิก | I8: - | J8: กฟก.3 | L8: รอดำเนินการหลังอนุมัติเชื่อมต่อ / รับพิจารณา | M8: =COUNTIF(H:H,"รอดำเนินการหลังอนุมัติเชื่อมต่อ / รับพิจารณา") -> 73 | N8: ราย
A9: PPIM18500122 | B9: 20003126379 | C9: บริษัท มหาชัย โฟรเซ่น ฟู้ดส์ จำกัด | D9: 45315.497 | E9: - | F9: 625 | G9: - | H9: ยกเลิก | I9: - | J9: กฟก.3 | L9: รอแก้ไขเอกสารหลังอนุมัติเชื่อมต่อ / รับพิจารณา | M9: =COUNTIF(H:H,"รอแก้ไขเอกสารหลังอนุมัติเชื่อมต่อ / รับพิจารณา") -> 79 | N9: ราย
A10: PPIM1850012B | B10: 89302002346 | C10: บริษัท เกรทฮิลล์ ฟู้ดส์ จำกัด | D10: 45315.589 | E10: - | F10: 300 | G10: - | H10: ยกเลิก | I10: - | J10: กฟก.3 | L10: รออนุมัติเชื่อมต่อ (200 kW ขึ้นไป) | M10: =COUNTIF(H:H,"รออนุมัติเชื่อมต่อ (200 kW ขึ้นไป)") -> 0 | N10: ราย
A11: PPIM18500136 | B11: 20025562782 | C11: นาง นราทิพย์ รู้ทวีผล | D11: 45315.636 | E11: - | F11: 25 | G11: - | H11: ยกเลิก | I11: - | J11: กฟก.3 | L11: รอตรวจสอบระบบผลิต | M11: =COUNTIF(H:H,"รอตรวจสอบระบบผลิต") -> 259 | N11: ราย
A12: PPIM1850013C | B12: 20003286438 | C12: บริษัท เอ็นจีเอ็ม อินดัสเตรียล จำกัด | D12: 45315.653 | E12: - | F12: 320 | G12: - | H12: ยกเลิก | I12: - | J12: กฟก.3 | L12: รอทดสอบเชื่อมต่อ | M12: =COUNTIF(H:H,"รอทดสอบเชื่อมต่อ") -> 7 | N12: ราย
A13: PPIM18500153 | B13: 9626478 | C13: น.ส.นัดทิพร ทับทอง | D13: 45316.468 | E13: - | F13: 200 | G13: - | H13: ยกเลิก | I13: - | J13: กฟก.3 | L13: รออนุมัติแจ้งวันเริ่มเชื่อมต่อ | M13: =COUNTIF(H:H,"รออนุมัติแจ้งวันเริ่มเชื่อมต่อ") -> 0 | N13: ราย
A14: PPIM18500163 | B14: 20003553708 | C14: สุวรรณ ธรรมาภิรักษ์ (บุญค้ำ โคนันท์) | D14: 45316.685 | E14: - | F14: 20 | G14: - | H14: ยกเลิก | I14: - | J14: กฟก.3 | L14: เชื่อมต่อเรียบร้อยแล้ว | M14: =COUNTIF(H:H,"เชื่อมต่อเรียบร้อยแล้ว") -> 301 | N14: ราย
A15: PPIM18500192 | B15: 20019789166 | C15: การไฟฟ้าส่วนภูมิภาคโคกขาม | D15: 45317.615 | E15: - | F15: 10 | G15: - | H15: ยกเลิก | I15: - | J15: กฟก.3
A16: PPIM185001A0 | B16: 20024804571 | C16: บริษัท ฉั่วฮะเส็ง ฟู้ดโปรดักส์ จำกัด | D16: 45317.7 | E16: - | F16: 20 | G16: - | H16: ยกเลิก | I16: - | J16: กฟก.3
A17: PPIM185001A6 | B17: 20003489829 | C17: บริษัท เอช.เค.ฟาร์มาซูติคอล จำกัด | D17: 45317.82 | E17: - | F17: 900 | G17: - | H17: ยกเลิก | I17: - | J17: กฟก.3
A18: PPIM185001B6 | B18: 20027112512 | C18: บริษัท สี่มิตรมหาชัย จำกัด | D18: 45318.64 | E18: - | F18: 10 | G18: - | H18: ยกเลิก | I18: - | J18: กฟก.3
A19: PPIM185001B7 | B19: 20003376856 | C19: บริษัท ปิยะมิตร มอเตอร์ จำกัด | D19: 45318.656 | E19: - | F19: 10 | G19: - | H19: ยกเลิก | I19: - | J19: กฟก.3
A20: PPIM185001C9 | B20: 20023705237 | C20: บริษัท ที.ซี.โพลีเวิร์ค จำกัด | D20: 45319.567 | E20: - | F20: 90 | G20: - | H20: ยกเลิก | I20: - | J20: กฟก.3
A21: PPIM185001CF | B21: 20003338223 | C21: บริษัท น้ำมันพืชไทย จำกัด (มหาชน) | D21: 45319.808 | E21: - | F21: 800 | G21: - | H21: ยกเลิก | I21: - | J21: กฟก.3
A22: PPIM185001EC | B22: 20020899563 | C22: บริษัท เอ็นจีเอ็ม-เอ็กซ์ จำกัด | D22: 45320.616 | E22: - | F22: 150 | G22: - | H22: ยกเลิก | I22: - | J22: กฟก.3
A23: PPIM185001F3 | B23: 20021417694 | C23: บริษัท นครยนต์ออโต้ซาวด์ 2560 จำกัด | D23: 45320.64 | E23: - | F23: 20 | G23: - | H23: ยกเลิก | I23: - | J23: กฟก.3
A24: PPIM1850020E | B24: 20017422499 | C24: นายวัชชา เกศวยุธ | D24: 45321.506 | E24: - | F24: 15 | G24: - | H24: ยกเลิก | I24: - | J24: กฟก.3
A25: PPIM18500229 | B25: 20026569497 | C25: บริษัท เด่นชัยการเคหะและที่ดิน จำกัด | D25: 45321.737 | E25: - | F25: 5 | G25: - | H25: ยกเลิก | I25: - | J25: กฟก.3
A26: PPIM1850022B | B26: 20026848221 | C26: บริษัท เด่นชัยการเคหะและที่ดิน จำกัด | D26: 45321.753 | E26: - | F26: 5 | G26: - | H26: ยกเลิก | I26: - | J26: กฟก.3
... A79: PPIM18500716 | B79: 20003409011 | C79: บริษัท รอยัล ยูนิเวอร์แซลเลซ จำกัด | D79: 45352.66 | E79: - | F79: 225 | G79: - | H79: ยกเลิก | I79: - | J79: กฟก.3
A80: PPIM18500719 | B80: 20027016386 | C80: บริษัท ซี.เจ. เอ็กซ์เพรส กรุ๊ป จำกัด | D80: 45352.682 | E80: - | F80: 30 | G80: 45533.471 | H80: รอดำเนินการหลังอนุมัติเชื่อมต่อ / รับพิจารณา | I80: - | J80: กฟก.3
A81: PPIM1850071A | B81: 20003408982 | C81: บริษัท รอยัล ยูนิเวอร์แซลเลซ จำกัด | D81: 45352.682 | E81: - | F81: 125 | G81: - | H81: ยกเลิก | I81: - | J81: กฟก.3
A82: PPIM18500727 | B82: 20018128165 | C82: บริษัท ไซเบอร์พริ้นท์กรุ๊ป จำกัด | D82: 45353.404 | E82: - | F82: 810 | G82: - | H82: ยกเลิก | I82: - | J82: กฟก.3
A83: PPIM18500733 | B83: 20021686238 | C83: บริษัท เมตตาภัทรวัสดภัณฑ์ จำกัด | D83: 45353.716 | E83: - | F83: 40 | G83: - | H83: ยกเลิก | I83: - | J83: กฟก.3
A84: PPIM18500738 | B84: 20026091278 | C84: บริษัท ไดนาสตี้ เซรามิค จำกัด (มหาชน) | D84: 45354.621 | E84: - | F84: 60 | G84: - | H84: ยกเลิก | I84: - | J84: กฟก.3
A85: PPIM1850073A | B85: 20026091278 | C85: บริษัท ไดนาสตี้ เซรามิค จำกัด (มหาชน) | D85: 45354.652 | E85: - | F85: 60 | G85: - | H85: ยกเลิก | I85: - | J85: กฟก.3
A86: PPIM1850073B | B86: 20026091278 | C86: บริษัท ไดนาสตี้ เซรามิค จำกัด(มหาชน) (สาขากาญจนบุรี) | D86: 45354.662 | E86: - | F86: 60 | G86: - | H86: ยกเลิก | I86: - | J86: กฟก.3
A87: PPIM18500741 | B87: 20020345333 | C87: บริษัท วี.อาร์.ทอยส์ จำกัด | D87: 45354.95 | E87: - | F87: 96 | G87: - | H87: ยกเลิก | I87: - | J87: กฟก.3
A88: PPIM18500750 | B88: 20026299076 | C88: บริษัท ดี-แลนด์ พร็อพเพอร์ตี้ จำกัด | D88: 45355.512 | E88: - | F88: 300 | G88: - | H88: ยกเลิก | I88: - | J88: กฟก.3
A89: PPIM18500779 | B89: 20026891697 | C89: นาย ธัญญ์นิธิ รู้ขายวงศ์เจริญ | D89: 45356.399 | E89: - | F89: 20 | G89: - | H89: ยกเลิก | I89: - | J89: กฟก.3
A90: PPIM185007A9 | B90: 200025025237 | C90: บริษัทกลุ่ม 15 จำกัด | D90: 45357.474 | E90: - | F90: 20 | G90: - | H90: ยกเลิก | I90: - | J90: กฟก.3
A91: PPIM185007C2 | B91: 20003480861 | C91: บริษัท สยามโพลีเน็ต จำกัด | D91: 45357.933 | E91: - | F91: 500 | G91: - | H91: ยกเลิก | I91: - | J91: กฟก.3
A92: PPIM185007D2 | B92: 20019001115 | C92: บริษัท นิวสตาร์ โฟรเซ่นฟู้ดส์(ไทยแลนด์) จำกัด | D92: 45358.465 | E92: - | F92: 331.2 | G92: - | H92: ยกเลิก | I92: - | J92: กฟก.3
...

Sheet กฟจ นฐ
A2: เลขที่คำขอ | B2: หมายเลข CA | C2: ชื่อผู้ใช้ไฟฟ้า | D2: วันที่ยื่นคำขอ | E2: วันที่ยื่นแก้ไขคำขอ | F2: กำลังการผลิต (kW) | G2: วันที่ชำระเงิน | H2: สถานะคำขอ | J2: พื้นที่ กฟฟ. | L2: รวม | M2: =COUNT(B:B) -> 250 | N2: ราย
A3: PPIM185000F3 | B3: 20027163223 | C3: น.ส.ณัฏฐยา โพธิพีรนันท์ | D3: 45314.474 | E3: - | F3: 3 | G3: - | H3: ยกเลิก | I3: - | J3: กฟจ.นครปฐม | L3: รอตรวจสอบคำขอ | M3: =COUNTIF(H:H,"รอตรวจสอบคำขอ") -> 0 | N3: ราย
A4: PPIM185001E7 | B4: 20018116166 | C4: สมชาติ สองสี | D4: 45320.578 | E4: - | F4: 10 | G4: - | H4: ยกเลิก | I4: - | J4: กฟอ.ดอนตูม | L4: ยกเลิก | M4: =COUNTIF(H:H,"ยกเลิก") -> 50 | N4: ราย
A5: PPIM185002C4 | B5: 20023433138 | C5: นายวิชัย งามศิริจิตร | D5: 45325.905 | E5: - | F5: 5 | G5: - | H5: ยกเลิก | I5: - | J5: กฟจ.นครปฐม | L5: รอผู้ยื่นคำขอส่งเอกสารแก้ไข | M5: =COUNTIF(H:H,"รอผู้ยื่นคำขอส่งเอกสารแก้ไข") -> 2 | N5: ราย
A6: PPIM185006BC | B6: 20002853791 | C6: นางทองล้วน สาวทรัพย์ | D6: 45350.705 | E6: - | F6: 10 | G6: - | H6: ยกเลิก | I6: - | J6: กฟจ.นครปฐม | L6: รอชำระเงิน | M6: =COUNTIF(H:H,"รอชำระเงิน") -> 44 | N6: ราย | O6: (รวม รอ หผ / อก / ผจก อนุมัติ ด้วย)
A7: PPIM185007E7 | B7: 20023342451 | C7: นายพรภวิษย์ บุญศรีเรือง | D7: 45358.606 | E7: - | F7: 5 | G7: - | H7: ยกเลิก | I7: - | J7: กฟจ.นครปฐม | L7: รออนุมัติเชื่อมต่อ/รับพิจารณา | M7: =COUNTIF(H:H,"รออนุมัติเชื่อมต่อ/รับพิจารณา")+COUNTIF(H:H,"รอ หผ. อนุมัติ")+COUNTIF(H:H,"รอ ผจก./อก. อนุมัติ") -> 2 | N7: ราย
A8: PPIM1850097B | B8: 20026213318 | C8: นาย อภิชาติ เพชรนุ้ย | D8: 45368.843 | E8: - | F8: 10 | G8: - | H8: ยกเลิก | I8: - | J8: กฟจ.นครปฐม | L8: รอดำเนินการหลังอนุมัติเชื่อมต่อ / รับพิจารณา | M8: =COUNTIF(H:H,"รอดำเนินการหลังอนุมัติเชื่อมต่อ / รับพิจารณา") -> 17 | N8: ราย
A9: PPIM18500AAF | B9: 20027094943 | C9: นาย อรรถพล บุญมี | D9: 45376.603 | E9: - | F9: 10 | G9: - | H9: ยกเลิก | I9: - | J9: กฟจ.นครปฐม | L9: รอแก้ไขเอกสารหลังอนุมัติเชื่อมต่อ / รับพิจารณา | M9: =COUNTIF(H:H,"รอแก้ไขเอกสารหลังอนุมัติเชื่อมต่อ / รับพิจารณา") -> 1 | N9: ราย
A10: PPIM18500B94 | B10: 20017796116 | C10: นางสาวนพรัตน์ ทองกำเหนิด | D10: 45383.608 | E10: - | F10: 3 | G10: - | H10: ยกเลิก | I10: - | J10: กฟจ.นครปฐม | L10: รออนุมัติเชื่อมต่อ (200 kW ขึ้นไป) | M10: =COUNTIF(H:H,"รออนุมัติเชื่อมต่อ (200 kW ขึ้นไป)") -> 0 | N10: ราย
A11: PPIM18500BAD | B11: 20027163223 | C11: น.ส.ณัฏฐยา โพธิพีรนันท์ | D11: 45384.355 | E11: - | F11: 3 | G11: - | H11: ยกเลิก | I11: - | J11: กฟจ.นครปฐม | L11: รอตรวจสอบระบบผลิต | M11: =COUNTIF(H:H,"รอตรวจสอบระบบผลิต") -> 2 | N11: ราย
A12: PPIM18500B7E | B12: 20002676443 | C12: น.ส.มยุลา ขันธสุวรรณ | D12: 45381.749 | E12: 45410.416 | F12: 5 | G12: 45482.36 | H12: เชื่อมต่อเรียบร้อยแล้ว | I12: - | J12: กฟจ.นครปฐม | L12: รอทดสอบเชื่อมต่อ | M12: =COUNTIF(H:H,"รอทดสอบเชื่อมต่อ") -> 0 | N12: ราย
A13: PPIM18500F2F | B13: 20027225860 | C13: นาง นลินภัสร์ คชกิจจารักษ์ | D13: 45411.999 | E13: - | F13: 5 | G13: - | H13: ยกเลิก | I13: - | J13: กฟจ.นครปฐม | L13: รออนุมัติแจ้งวันเริ่มเชื่อมต่อ | M13: =COUNTIF(H:H,"รออนุมัติแจ้งวันเริ่มเชื่อมต่อ") -> 0 | N13: ราย
A14: PPIM18500F62 | B14: 20018116166 | C14: นาย สมชาติ สองสี | D14: 45412.707 | E14: - | F14: 10 | G14: 45827.584 | H14: เชื่อมต่อเรียบร้อยแล้ว | I14: - | J14: กฟอ.ดอนตูม | L14: เชื่อมต่อเรียบร้อยแล้ว | M14: =COUNTIF(H:H,"เชื่อมต่อเรียบร้อยแล้ว") -> 132 | N14: ราย
A15: PPIM1850092C | B15: 20023342451 | C15: พรภวิษย์ บุญศรีเมือง | D15: 45365.684 | E15: 45414.437 | F15: 5 | G15: 45481.449 | H15: เชื่อมต่อเรียบร้อยแล้ว | I15: - | J15: กฟจ.นครปฐม
A16: PPIM18500F95 | B16: 20023593873 | C16: นายภาษภูมิ พุทธไพศาล | D16: 45414.499 | E16: - | F16: 2 | G16: 45471.496 | H16: เชื่อมต่อเรียบร้อยแล้ว | I16: - | J16: กฟจ.นครปฐม
A17: PPIM185001D1 | B17: 20002675170 | C17: นายสาธิต ชุมนุสนธิ์ | D17: 45319.86 | E17: 45418.399 | F17: 5 | G17: - | H17: รอชำระเงิน | I17: - | J17: กฟจ.นครปฐม
A18: PPIM185010C7 | B18: 20024838539 | C18: น.ส.จิตระวี ขุนทอง | D18: 45421.514 | E18: - | F18: 5 | G18: - | H18: ยกเลิก | I18: - | J18: กฟจ.นครปฐม
A19: PPIM185010E4 | B19: 20021611132 | C19: บริษัท อินเตอร์เวชภัณฑ์ จำกัด | D19: 45421.984 | E19: - | F19: 5 | G19: - | H19: ยกเลิก | I19: - | J19: กฟจ.นครปฐม
A20: PPIM18500B78 | B20: 20021378623 | C20: นางเฉลิมวงษ์ บรรจงจิตร์ | D20: 45381.489 | E20: 45427.475 | F20: 10 | G20: 45461.588 | H20: เชื่อมต่อเรียบร้อยแล้ว | I20: - | J20: กฟจ.นครปฐม
A21: PPIM185011CE | B21: 20023435176 | C21: นายถวัลย์ พบลาภ | D21: 45427.64 | E21: - | F21: 5 | G21: - | H21: ยกเลิก | I21: - | J21: กฟจ.นครปฐม
A22: PPIM18500CF3 | B22: 20002943286 | C22: บริษัท ไทยแลนด์ ออโต เซลส์ จำกัด | D22: 45391.877 | E22: 45428.056 | F22: 10 | G22: 45469.607 | H22: เชื่อมต่อเรียบร้อยแล้ว | I22: - | J22: กฟจ.นครปฐม
A23: PPIM1850122D | B23: 20017742076 | C23: นายบุญชู สุขสถาพรเลิศ | D23: 45429.58 | E23: - | F23: 6 | G23: 45842.449 | H23: เชื่อมต่อเรียบร้อยแล้ว | I23: - | J23: กฟอ.ดอนตูม
A24: PPIM18501311 | B24: 20002764424 | C24: นายสมหวัง ฤทธิ์ณรงค์ | D24: 45433.652 | E24: - | F24: 5 | G24: 45483.562 | H24: เชื่อมต่อเรียบร้อยแล้ว | I24: - | J24: กฟจ.นครปฐม
A25: PPIM18501328 | B25: 20023039250 | C25: นายโยธิน ชาวนาวิก | D25: 45433.922 | E25: - | F25: 5 | G25: - | H25: ยกเลิก | I25: - | J25: กฟจ.นครปฐม
A26: PPIM1850111F | B26: 20027094943 | C26: อรรถพล บุญมี | D26: 45423.653 | E26: 45441.472 | F26: 10 | G26: 45464.633 | H26: เชื่อมต่อเรียบร้อยแล้ว | I26: - | J26: กฟจ.นครปฐม
A27: PPIM185014CB | B27: 20002707372 | C27: นายพิศิษฐ ศุภมัสดุอังกูร | D27: 45442.494 | E27: - | F27: 3 | G27: - | H27: ยกเลิก | I27: - | J27: กฟจ.นครปฐม
A28: PPIM18501436 | B28: 20026472842 | C28: บริษัท เชลล์แห่งประเทศไทย จำกัด | D28: 45440.415 | E28: 45442.606 | F28: 16.836 | G28: 45476.653 | H28: เชื่อมต่อเรียบร้อยแล้ว | I28: - | J28: กฟจ.นครปฐม
A29: PPIM18501546 | B29: 20027163223 | C29: น.ส.ณัฏฐยา โพธิพีรนันท์ | D29: 45443.583 | E29: - | F29: 3 | G29: 45463.414 | H29: เชื่อมต่อเรียบร้อยแล้ว | I29: - | J29: กฟจ.นครปฐม
A30: PPIM18501367 | B30: 20002853791 | C30: นางทองล้วน สาวทรัพย์ | D30: 45435.553 | E30: 45447.355 | F30: 10 | G30: 45464.609 | H30: เชื่อมต่อเรียบร้อยแล้ว | I30: - | J30: กฟจ.นครปฐม
A31: PPIM18501437 | B31: 20026980901 | C31: นายจิรภัทร มากบุญงาม | D31: 45440.419 | E31: 45447.475 | F31: 10 | G31: 45462.549 | H31: เชื่อมต่อเรียบร้อยแล้ว | I31: - | J31: กฟจ.นครปฐม
A32: PPIM185015D7 | B32: 20017561720 | C32: นายเจริญชัย คล้ายทวน | D32: 45448.558 | E32: - | F32: 4 | G32: - | H32: ยกเลิก | I32: - | J32: กฟจ.นครปฐม
A33: PPIM185016F2 | B33: 20026070112 | C33: บริษัท เอสพี-วัน พียูรูฟส์ จำกัด | D33: 45453.719 | E33: - | F33: 20 | G33: 45783.469 | H33: เชื่อมต่อเรียบร้อยแล้ว | I33: - | J33: กฟอ.ดอนตูม
A34: PPIM185016F3 | B34: 20026070112 | C34: บริษัท เอสพี-วัน พียูรูฟส์ จำกัด | D34: 45453.727 | E34: - | F34: 20 | G34: - | H34: ยกเลิก | I34: - | J34: กฟอ.ดอนตูม
A35: PPIM18501759 | B35: 20024842226 | C35: สิริชัย นับดี | D35: 45456.419 | E35: - | F35: 20 | G35: 45475.635 | H35: เชื่อมต่อเรียบร้อยแล้ว | I35: - | J35: กฟจ.นครปฐม
A36: PPIM18501835 | B36: 20019867913 | C36: นาย บุญเตี้ยง มั่นคง | D36: 45460.407 | E36: - | F36: 4 | G36: - | H36: ยกเลิก | I36: - | J36: กฟจ.นครปฐม
A37: PPIM18501866 | B37: 20023435716 | C37: นายถวัลย์ พบลาภ | D37: 45460.689 | E37: - | F37: 5 | G37: - | H37: ยกเลิก | I37: - | J37: กฟจ.นครปฐม
A38: PPIM185018EE | B38: 20018355913 | C38: น.ส.เซาะไน้ แซ่ลี้ | D38: 45462.783 | E38: 45465.738 | F38: 5 | G38: 45471.496 | H38: เชื่อมต่อเรียบร้อยแล้ว | I38: - | J38: กฟจ.นครปฐม
A39: PPIM18501A27 | B39: 20002760034 | C39: นาย เสวย แก้วสมบูรณ์ | D39: 45468.603 | E39: - | F39: 10 | G39: 45474.526 | H39: เชื่อมต่อเรียบร้อยแล้ว | I39: - | J39: กฟจ.นครปฐม
A40: PPIM18501A2F | B40: 20002957188 | C40: นายนันทวัช พุทธคุณรักษา | D40: 45468.642 | E40: - | F40: 15 | G40: - | H40: ยกเลิก | I40: - | J40: กฟจ.นครปฐม
A41: PPIM185015F8 | B41: 20027639490 | C41: น.ส.ขนิษฐา บุษบา | D41: 45448.69 | E41: 45468.993 | F41: 4 | G41: - | H41: รอชำระเงิน | I41: - | J41: กฟจ.นครปฐม
...

Sheet กฟส นครชัยศรี
A2: เลขที่คำขอ | B2: หมายเลข CA | C2: ชื่อผู้ใช้ไฟฟ้า | D2: วันที่ยื่นคำขอ | E2: วันที่ยื่นแก้ไขคำขอ | F2: กำลังการผลิต (kW) | G2: วันที่ชำระเงิน | H2: สถานะคำขอ | J2: พื้นที่ กฟฟ. | L2: รวม | M2: =COUNT(B:B) -> 102 | N2: ราย
A3: PPIM185009D0 | B3: 20026027222 | C3: นางประจิน มุกดาหาร | D3: 45371.488 | E3: - | F3: 5 | G3: - | H3: ยกเลิก | I3: - | J3: กฟอ.นครชัยศรี | L3: รอตรวจสอบคำขอ | M3: =COUNTIF(H:H,"รอตรวจสอบคำขอ") -> 10 | N3: ราย
A4: PPIM18500CF2 | B4: 20003464087 | C4: นางสมจิตร ศรีเพ็ง | D4: 45391.86 | E4: - | F4: 5 | G4: - | H4: ยกเลิก | I4: - | J4: กฟอ.นครชัยศรี | L4: ยกเลิก | M4: =COUNTIF(H:H,"ยกเลิก") -> 58 | N4: ราย
A5: PPIM18500DD0 | B5: 20002575303 | C5: นางสาว ธัญญานุช ทองยอดพันธ์ | D5: 45401.668 | E5: - | F5: 5 | G5: - | H5: ยกเลิก | I5: - | J5: กฟอ.นครชัยศรี | L5: รอผู้ยื่นคำขอส่งเอกสารแก้ไข | M5: =COUNTIF(H:H,"รอผู้ยื่นคำขอส่งเอกสารแก้ไข") -> 0 | N5: ราย
A6: PPIM18500133 | B6: 20003495624 | C6: นางสำรวง สุขชื่นชม | D6: 45315.619 | E6: 45427.67 | F6: 10 | G6: 45456.624 | H6: เชื่อมต่อเรียบร้อยแล้ว | I6: - | J6: กฟอ.นครชัยศรี | L6: รอชำระเงิน | M6: =COUNTIF(H:H,"รอชำระเงิน") -> 2 | N6: ราย | O6: (รวม รอ หผ / อก / ผจก อนุมัติ ด้วย)
A7: PPIM18500F86 | B7: 20026819749 | C7: นายสิทธิชัย เนตรประดิษฐ์ | D7: 45414.406 | E7: 45433.662 | F7: 15 | G7: - | H7: ยกเลิก | I7: - | J7: กฟอ.นครชัยศรี | L7: รออนุมัติเชื่อมต่อ/รับพิจารณา | M7: =COUNTIF(H:H,"รออนุมัติเชื่อมต่อ/รับพิจารณา")+COUNTIF(H:H,"รอ หผ. อนุมัติ")+COUNTIF(H:H,"รอ ผจก./อก. อนุมัติ") -> 4 | N7: ราย
A8: PPIM18501602 | B8: 20003366734 | C8: นาย พิพัฒน์ ศิริชัย | D8: 45448.822 | E8: - | F8: 5 | G8: - | H8: ยกเลิก | I8: - | J8: กฟอ.นครชัยศรี | L8: รอดำเนินการหลังอนุมัติเชื่อมต่อ / รับพิจารณา | M8: =COUNTIF(H:H,"รอดำเนินการหลังอนุมัติเชื่อมต่อ / รับพิจารณา") -> 2 | N8: ราย
A9: PPIM185016E0 | B9: 20026027280 | C9: นางประจิน มุกดาหาร | D9: 45453.621 | E9: - | F9: 5 | G9: 45492.526 | H9: เชื่อมต่อเรียบร้อยแล้ว | I9: - | J9: กฟอ.นครชัยศรี | L9: รอแก้ไขเอกสารหลังอนุมัติเชื่อมต่อ / รับพิจารณา | M9: =COUNTIF(H:H,"รอแก้ไขเอกสารหลังอนุมัติเชื่อมต่อ / รับพิจารณา") -> 0 | N9: ราย
A10: PPIM185016EA | B10: 20025246220 | C10: บริษัท เอสพี-วัน เมทัลชีท เทรดดิ้ง จำกัด | D10: 45453.701 | E10: - | F10: 15 | G10: - | H10: ยกเลิก | I10: - | J10: กฟอ.นครชัยศรี | L10: รออนุมัติเชื่อมต่อ (200 kW ขึ้นไป) | M10: =COUNTIF(H:H,"รออนุมัติเชื่อมต่อ (200 kW ขึ้นไป)") -> 0 | N10: ราย
A11: PPIM18501758 | B11: 20019725700 | C11: นันทิศา ชาติชาญชัย | D11: 45455.553 | E11: - | F11: 8 | G11: - | H11: ยกเลิก | I11: - | J11: กฟอ.นครชัยศรี | L11: รอตรวจสอบระบบผลิต | M11: =COUNTIF(H:H,"รอตรวจสอบระบบผลิต") -> 1 | N11: ราย
A12: PPIM18501382 | B12: 20003310398 | C12: นาย ไตร ปริปุณณานนท์ | D12: 45435.863 | E12: 45460.86 | F12: 10 | G12: 45490.547 | H12: เชื่อมต่อเรียบร้อยแล้ว | I12: - | J12: กฟอ.นครชัยศรี | L12: รอทดสอบเชื่อมต่อ | M12: =COUNTIF(H:H,"รอทดสอบเชื่อมต่อ") -> 0 | N12: ราย
A13: PPIM185018F0 | B13: 20003366734 | C13: นาย พิพัฒน์ ศิริชัย | D13: 45462.905 | E13: - | F13: 5 | G13: - | H13: ยกเลิก | I13: - | J13: กฟอ.นครชัยศรี | L13: รออนุมัติแจ้งวันเริ่มเชื่อมต่อ | M13: =COUNTIF(H:H,"รออนุมัติแจ้งวันเริ่มเชื่อมต่อ") -> 0 | N13: ราย
A14: PPIM1850194C | B14: 20025246220 | C14: บริษัท เอสพี-วัน เมทัลชีท เทรดดิ้ง จำกัด | D14: 45464.46 | E14: - | F14: 15 | G14: 45512.599 | H14: เชื่อมต่อเรียบร้อยแล้ว | I14: - | J14: กฟอ.นครชัยศรี | L14: เชื่อมต่อเรียบร้อยแล้ว | M14: =COUNTIF(H:H,"เชื่อมต่อเรียบร้อยแล้ว") -> 25 | N14: ราย
A15: PPIM18501B33 | B15: 20027665825 | C15: นายศิษฎี ศรคุปต์ | D15: 45472.547 | E15: - | F15: 5 | G15: - | H15: ยกเลิก | I15: - | J15: กฟอ.นครชัยศรี
A16: PPIM18501BC3 | B16: 20026584113 | C16: บริษัท พีแอล โค่ย | D16: 45475.678 | E16: - | F16: 10 | G16: - | H16: ยกเลิก | I16: - | J16: กฟอ.นครชัยศรี
A17: PPIM18501BF6 | B17: 20003575303 | C17: น.ส.ธัญญานุช ทองยอดพันธ์ | D17: 45476.674 | E17: - | F17: 5 | G17: - | H17: ยกเลิก | I17: - | J17: กฟอ.นครชัยศรี
A18: PPIM18501C59 | B18: 20019725700 | C18: นาง นันทิศา ชาติชาญชัย | D18: 45478.401 | E18: - | F18: 8 | G18: - | H18: ยกเลิก | I18: - | J18: กฟอ.นครชัยศรี
A19: PPIM18501A8B | B19: 20026819749 | C19: นายสิทธิชัย เนตรประดิษฐ์ | D19: 45469.696 | E19: 45482.672 | F19: 15 | G19: - | H19: ยกเลิก | I19: - | J19: กฟอ.นครชัยศรี
A20: PPIM18501A88 | B20: 20003627666 | C20: นายกุลชัย วิรุฬห์ภูติ | D20: 45469.69 | E20: 45484.431 | F20: 20 | G20: - | H20: ยกเลิก | I20: - | J20: กฟอ.นครชัยศรี
A21: PPIM185019BB | B21: 20025520914 | C21: นายชนิต เหล่าขจรบุญ | D21: 45467.485 | E21: 45488.501 | F21: 10 | G21: 45524.41 | H21: เชื่อมต่อเรียบร้อยแล้ว | I21: - | J21: กฟอ.นครชัยศรี
A22: PPIM18500AFD | B22: 20025696667 | C22: นายสกนต์ อยู่พะเนียด | D22: 45378.585 | E22: 45490.656 | F22: 4 | G22: 45552.621 | H22: เชื่อมต่อเรียบร้อยแล้ว | I22: - | J22: กฟอ.นครชัยศรี
A23: PPIM18501FE1 | B23: 20022335153 | C23: บริษัท วินเทค อะโกร จำกัด | D23: 45491.431 | E23: - | F23: 10 | G23: - | H23: เชื่อมต่อเรียบร้อยแล้ว | I23: - | J23: กฟอ.นครชัยศรี
A24: PPIM18501FF3 | B24: 20027665825 | C24: นายศิษฎี ศรคุปต์ | D24: 45491.483 | E24: - | F24: 5 | G24: - | H24: ยกเลิก | I24: - | J24: กฟอ.นครชัยศรี
A25: PPIM18502038 | B25: 20003627666 | C25: นายกลุชัย วิรุฬห์ภูติ5 | D25: 45492.428 | E25: - | F25: 20 | G25: - | H25: ยกเลิก | I25: - | J25: กฟอ.นครชัยศรี
A26: PPIM18500B60 | B26: 20022141629 | C26: นางสาว ตรีสุคนธ์ ทองชัยเดช | D26: 45380.659 | E26: 45492.525 | F26: 5 | G26: 45534.334 | H26: เชื่อมต่อเรียบร้อยแล้ว | I26: - | J26: กฟอ.นครชัยศรี
A27: PPIM18502207 | B27: 20003627666 | C27: นายกุลชัย วิรุฬห์ภูติ | D27: 45499.423 | E27: - | F27: 20 | G27: - | H27: ยกเลิก | I27: - | J27: กฟอ.นครชัยศรี
A28: PPIM1850199F | B28: 20003366734 | C28: นาย พิพัฒน์ ศิริชัย | D28: 45465.738 | E28: 45499.452 | F28: 5 | G28: - | H28: ยกเลิก | I28: - | J28: กฟอ.นครชัยศรี
A29: PPIM1850242B | B29: 20026819749 | C29: 3730300205528 | D29: 45511.684 | E29: - | F29: 15 | G29: - | H29: ยกเลิก | I29: - | J29: กฟอ.นครชัยศรี
A30: PPIM185024AE | B30: 20019725700 | C30: นางนันทิศา ชาติชาญชัย | D30: 45513.476 | E30: - | F30: 2 | G30: - | H30: ยกเลิก | I30: - | J30: กฟอ.นครชัยศรี
A31: PPIM18502587 | B31: 20026819749 | C31: นายสิทธิชัย เนตรประดิษฐ์ | D31: 45517.629 | E31: - | F31: 15 | G31: 45545.44 | H31: เชื่อมต่อเรียบร้อยแล้ว | I31: - | J31: กฟอ.นครชัยศรี
A32: PPIM18502609 | B32: 20003308194 | C32: นาย พาท มีชำนาญ | D32: 45518.834 | E32: - | F32: 5 | G32: - | H32: ยกเลิก | I32: - | J32: กฟอ.นครชัยศรี
A33: PPIM185027DC | B33: 20019725700 | C33: นางนันทิศา ชาติชาญชัย | D33: 45525.447 | E33: - | F33: 8 | G33: - | H33: ยกเลิก | I33: - | J33: กฟอ.นครชัยศรี
A34: PPIM18501FB1 | B34: 20026584113 | C34: บริษัท พีแอล โค่ย จำกัด | D34: 45490.651 | E34: 45525.691 | F34: 10 | G34: - | H34: ยกเลิก | I34: - | J34: กฟอ.นครชัยศรี
A35: PPIM18502129 | B35: 20021169223 | C35: นาง รติกร เศรษฐพิทยากุล | D35: 45496.931 | E35: 45525.903 | F35: 12 | G35: 45554.407 | H35: เชื่อมต่อเรียบร้อยแล้ว | I35: - | J35: กฟอ.นครชัยศรี
A36: PPIM185028BD | B36: 20026487706 | C36: นายอินทร์จันทร์ บุราพันธ์ | D36: 45527.691 | E36: - | F36: 10 | G36: - | H36: ยกเลิก | I36: - | J36: กฟอ.นครชัยศรี
A37: PPIM18501E20 | B37: 20022873351 | C37: นาย สิทธิพงษ์ ศิริสถิตย์ | D37: 45484.968 | E37: 45531.48 | F37: 20 | G37: 45540.411 | H37: เชื่อมต่อเรียบร้อยแล้ว | I37: - | J37: กฟอ.นครชัยศรี
A38: PPIM185029C2 | B38: 20017968396 | C38: พีระ นนพิจิตร | D38: 45531.727 | E38: - | F38: 3 | G38: - | H38: ยกเลิก | I38: - | J38: กฟอ.นครชัยศรี
A39: PPIM185020BD | B39: 20026474087 | C39: นายเดชาธร วงศ์สวรรค์ | D39: 45495.551 | E39: 45532.675 | F39: 5 | G39: 45646.576 | H39: เชื่อมต่อเรียบร้อยแล้ว | I39: - | J39: กฟอ.นครชัยศรี
A40: PPIM18502A82 | B40: 20003546499 | C40: นายสมชาติ พรรณพัฒน์ | D40: 45533.756 | E40: - | F40: 10 | G40: - | H40: ยกเลิก | I40: - | J40: กฟอ.นครชัยศรี
A41: PPIM18502AC6 | B41: 20003366734 | C41: นาย พิพัฒน์ ศิริชัย | D41: 45534.683 | E41: - | F41: 5 | G41: 45638.525 | H41: เชื่อมต่อเรียบร้อยแล้ว | I41: - | J41: กฟอ.นครชัยศรี
...

Sheet กฟส กำแพงแสน
A2: เลขที่คำขอ | B2: หมายเลข CA | C2: ชื่อผู้ใช้ไฟฟ้า | D2: วันที่ยื่นคำขอ | E2: วันที่ยื่นแก้ไขคำขอ | F2: กำลังการผลิต (kW) | G2: วันที่ชำระเงิน | H2: สถานะคำขอ | J2: พื้นที่ กฟฟ. | L2: รวม | M2: =COUNT(B:B) -> 86 | N2: ราย
A3: PPIM18500BE7 | B3: 20020177062 | C3: พรชัย จานิมิตร | D3: 45384.97 | E3: - | F3: 20 | G3: 45509.449 | H3: เชื่อมต่อเรียบร้อยแล้ว | I3: - | J3: กฟอ.กำแพงแสน | L3: รอตรวจสอบคำขอ | M3: =COUNTIF(H:H,"รอตรวจสอบคำขอ") -> 2 | N3: ราย
A4: PPIM18500CDF | B4: 20023723483 | C4: บริษัท เคพีเอส คาเฟ่จำกัด | D4: 45391.626 | E4: - | F4: 10 | G4: - | H4: ยกเลิก | I4: - | J4: กฟอ.กำแพงแสน | L4: ยกเลิก | M4: =COUNTIF(H:H,"ยกเลิก") -> 44 | N4: ราย
A5: PPIM18501001 | B5: 20003268918 | C5: นางแซ่เล็ก เลาศรีรัตนชัย | D5: 45415.976 | E5: 45438.878 | F5: 10 | G5: 45512.483 | H5: เชื่อมต่อเรียบร้อยแล้ว | I5: - | J5: กฟอ.กำแพงแสน | L5: รอผู้ยื่นคำขอส่งเอกสารแก้ไข | M5: =COUNTIF(H:H,"รอผู้ยื่นคำขอส่งเอกสารแก้ไข") -> 1 | N5: ราย
A6: PPIM1850129E | B6: 20003279636 | C6: บริษัท วัสดุภัณฑ์คอนกรีต จำกัด | D6: 45432.438 | E6: 45442.703 | F6: 10 | G6: 45490.465 | H6: เชื่อมต่อเรียบร้อยแล้ว | I6: - | J6: กฟอ.กำแพงแสน | L6: รอชำระเงิน | M6: =COUNTIF(H:H,"รอชำระเงิน") -> 3 | N6: ราย | O6: (รวม รอ หผ / อก / ผจก อนุมัติ ด้วย)
A7: PPIM18500E7A | B7: 20023723483 | C7: บริษัท เคพีเอส คาเฟ่ จำกัด | D7: 45406.701 | E7: 45448.705 | F7: 10 | G7: 45489.608 | H7: เชื่อมต่อเรียบร้อยแล้ว | I7: - | J7: กฟอ.กำแพงแสน | L7: รออนุมัติเชื่อมต่อ/รับพิจารณา | M7: =COUNTIF(H:H,"รออนุมัติเชื่อมต่อ/รับพิจารณา")+COUNTIF(H:H,"รอ หผ. อนุมัติ")+COUNTIF(H:H,"รอ ผจก./อก. อนุมัติ") -> 1 | N7: ราย
A8: PPIM18501806 | B8: 20026373502 | C8: นางสาวโสรยา งามไพลิน | D8: 45457.753 | E8: - | F8: 10 | G8: 45513.447 | H8: เชื่อมต่อเรียบร้อยแล้ว | I8: - | J8: กฟอ.กำแพงแสน | L8: รอดำเนินการหลังอนุมัติเชื่อมต่อ / รับพิจารณา | M8: =COUNTIF(H:H,"รอดำเนินการหลังอนุมัติเชื่อมต่อ / รับพิจารณา") -> 7 | N8: ราย
A9: PPIM18501880 | B9: 20025483104 | C9: ประพล แซ่เเต้ | D9: 45461.39 | E9: - | F9: 5 | G9: - | H9: ยกเลิก | I9: - | J9: กฟอ.กำแพงแสน | L9: รอแก้ไขเอกสารหลังอนุมัติเชื่อมต่อ / รับพิจารณา | M9: =COUNTIF(H:H,"รอแก้ไขเอกสารหลังอนุมัติเชื่อมต่อ / รับพิจารณา") -> 1 | N9: ราย
A10: PPIM185016D5 | B10: 20023900026 | C10: นายโกวิท ห่วงเนาวกุล | D10: 45453.558 | E10: 45471.661 | F10: 4 | G10: - | H10: ยกเลิก | I10: - | J10: กฟอ.กำแพงแสน | L10: รออนุมัติเชื่อมต่อ (200 kW ขึ้นไป) | M10: =COUNTIF(H:H,"รออนุมัติเชื่อมต่อ (200 kW ขึ้นไป)") -> 0 | N10: ราย
A11: PPIM18501B5C | B11: 20023900026 | C11: นายโกวิท ห่วงเนาวกุล | D11: 45474.433 | E11: - | F11: 4 | G11: 45483.365 | H11: เชื่อมต่อเรียบร้อยแล้ว | I11: - | J11: กฟอ.กำแพงแสน | L11: รอตรวจสอบระบบผลิต | M11: =COUNTIF(H:H,"รอตรวจสอบระบบผลิต") -> 1 | N11: ราย
A12: PPIM185020A5 | B12: 20003569382 | C12: นาวาอากาศเอกหญิง รัชนี ทองมี | D12: 45494.969 | E12: - | F12: 5 | G12: - | H12: ยกเลิก | I12: - | J12: กฟอ.กำแพงแสน | L12: รอทดสอบเชื่อมต่อ | M12: =COUNTIF(H:H,"รอทดสอบเชื่อมต่อ") -> 0 | N12: ราย
A13: PPIM185021DA | B13: 20003430883 | C13: ธนาคารออมสิน | D13: 45498.698 | E13: - | F13: 5 | G13: - | H13: ยกเลิก | I13: - | J13: กฟอ.กำแพงแสน | L13: รออนุมัติแจ้งวันเริ่มเชื่อมต่อ | M13: =COUNTIF(H:H,"รออนุมัติแจ้งวันเริ่มเชื่อมต่อ") -> 0 | N13: ราย
A14: PPIM18502198 | B14: 20025483104 | C14: ประพล แซ่เเต้ | D14: 45498.399 | E14: 45523.629 | F14: 5 | G14: 45546.62 | H14: เชื่อมต่อเรียบร้อยแล้ว | I14: - | J14: กฟอ.กำแพงแสน | L14: เชื่อมต่อเรียบร้อยแล้ว | M14: =COUNTIF(H:H,"เชื่อมต่อเรียบร้อยแล้ว") -> 26 | N14: ราย
A15: PPIM18502920 | B15: 20019463789 | C15: บริษัท ทรู มูฟ เอช ยูนิเวอร์แซล คอมมิวนิเคชั่น จำกัด | D15: 45530.496 | E15: - | F15: 12 | G15: - | H15: ยกเลิก | I15: - | J15: กฟอ.กำแพงแสน
A16: PPIM18502CA1 | B16: 20003450375 | C16: นายพันธ์ศักดิ์ จันทร์ชู | D16: 45541.597 | E16: - | F16: 5 | G16: - | H16: ยกเลิก | I16: - | J16: กฟอ.กำแพงแสน
A17: PPIM18502CF5 | B17: 20003554649 | C17: นางสาวดวงดาว แสงสาด | D17: 45542.653 | E17: - | F17: 10 | G17: - | H17: ยกเลิก | I17: - | J17: กฟอ.กำแพงแสน
A18: PPIM1850303C | B18: 20003450375 | C18: น.ต.พันธ์ศักดิ์ จันทรชู | D18: 45554.471 | E18: - | F18: 5 | G18: - | H18: ยกเลิก | I18: - | J18: กฟอ.กำแพงแสน
A19: PPIM185030EB | B19: 20003450375 | C19: น.ต.พันธ์ศักดิ์ จันทรชู | D19: 45555.745 | E19: - | F19: 5 | G19: - | H19: ยกเลิก | I19: - | J19: กฟอ.กำแพงแสน
A20: PPIM185030F4 | B20: 20003554649 | C20: นางดวงดาว แสงสาด | D20: 45556.365 | E20: - | F20: 10 | G20: - | H20: ยกเลิก | I20: - | J20: กฟอ.กำแพงแสน
A21: PPIM1850312B | B21: 20003529869 | C21: วัดสระมงคล | D21: 45557.894 | E21: - | F21: 10 | G21: - | H21: ยกเลิก | I21: - | J21: กฟอ.กำแพงแสน
A22: PPIM18503131 | B22: 20019919565 | C22: นายศุภเทพ ศรีสันต์ | D22: 45557.933 | E22: 45559.461 | F22: 5 | G22: 45593.61 | H22: เชื่อมต่อเรียบร้อยแล้ว | I22: - | J22: กฟอ.กำแพงแสน
A23: PPIM185034A5 | B23: 20003450375 | C23: น.ต.พันธ์ศักดิ์ จันทรชู | D23: 45568.584 | E23: - | F23: 5 | G23: 45603.431 | H23: เชื่อมต่อเรียบร้อยแล้ว | I23: - | J23: กฟอ.กำแพงแสน
A24: PPIM1850350C | B24: 20028043499 | C24: นางสาว เพียงทิพย์ ลาโภดม | D24: 45569.652 | E24: - | F24: 5 | G24: 45576.649 | H24: เชื่อมต่อเรียบร้อยแล้ว | I24: - | J24: กฟอ.กำแพงแสน
A25: PPIM18503483 | B25: 20003554649 | C25: นางสาวดวงดาว แสงสาด | D25: 45568.452 | E25: 45575.71 | F25: 10 | G25: 45594.544 | H25: เชื่อมต่อเรียบร้อยแล้ว | I25: - | J25: กฟอ.กำแพงแสน
A26: PPIM18503B1C | B26: 20027691252 | C26: พงศกร กู๊ดคาร์ จำกัด | D26: 45593.41 | E26: - | F26: 10 | G26: - | H26: ยกเลิก | I26: - | J26: กฟอ.กำแพงแสน
A27: PPIM18503C05 | B27: 20018237455 | C27: น.ส.นิสากร กระแจเหิน | D27: 45595.664 | E27: - | F27: 5 | G27: 45622.588 | H27: เชื่อมต่อเรียบร้อยแล้ว | I27: - | J27: กฟอ.กำแพงแสน
A28: PPIM18503CCA | B28: 20003529869 | C28: วัดสระมงคล | D28: 45599.319 | E28: - | F28: 10 | G28: 45608.409 | H28: เชื่อมต่อเรียบร้อยแล้ว | I28: - | J28: กฟอ.กำแพงแสน
A29: PPIM18503857 | B29: 20003460359 | C29: นายโฆษิต สาตนุรักษ์ | D29: 45581.572 | E29: 45600.61 | F29: 5 | G29: - | H29: เชื่อมต่อเรียบร้อยแล้ว | I29: - | J29: กฟอ.กำแพงแสน
A30: PPIM1850385A | B30: 20002900711 | C30: นายเริงชาย ธนะเกียรติไกร | D30: 45581.579 | E30: 45600.611 | F30: 5 | G30: - | H30: เชื่อมต่อเรียบร้อยแล้ว | I30: - | J30: กฟอ.กำแพงแสน
A31: PPIM18503E73 | B31: 20026237992 | C31: นางสาวศิริวรรณ พึ่งประชา | D31: 45604.444 | E31: - | F31: 10 | G31: 45653.567 | H31: เชื่อมต่อเรียบร้อยแล้ว | I31: - | J31: กฟอ.กำแพงแสน
A32: PPIM18503E82 | B32: 20026651986 | C32: บริษัท ทรู มูฟ เอช ยูนิเวอร์แซล คอมมิวนิเคชั่นจำกัด | D32: 45604.505 | E32: - | F32: 6 | G32: - | H32: ยกเลิก | I32: - | J32: กฟอ.กำแพงแสน
A33: PPIM18503FCE | B33: 20003430883 | C33: ธนาคารออมสิน | D33: 45609.61 | E33: - | F33: 5 | G33: - | H33: ยกเลิก | I33: - | J33: กฟอ.กำแพงแสน
A34: PPIM18504038 | B34: 20026429061 | C34: น.ส.ชลลดา พันธุ์โพธิ์ | D34: 45610.54 | E34: - | F34: 3.325 | G34: - | H34: ยกเลิก | I34: - | J34: กฟอ.กำแพงแสน
A35: PPIM185040A4 | B35: 20027691252 | C35: บริษัท พงศกร กู๊ดคาร์ จำกัด | D35: 45611.486 | E35: - | F35: 10 | G35: 45628.388 | H35: เชื่อมต่อเรียบร้อยแล้ว | I35: - | J35: กฟอ.กำแพงแสน
A36: PPIM185041D7 | B36: 20003430883 | C36: ธนาคารออมสิน สาขากำแพงแสน | D36: 45616.494 | E36: - | F36: 5 | G36: 45622.494 | H36: เชื่อมต่อเรียบร้อยแล้ว | I36: - | J36: กฟอ.กำแพงแสน
A37: PPIM185042B8 | B37: 20003529609 | C37: นาย เสริม มีผิวหอม | D37: 45618.663 | E37: - | F37: 15 | G37: - | H37: ยกเลิก | I37: - | J37: กฟอ.กำแพงแสน
A38: PPIM1850433F | B38: 20003491688 | C38: บริษัท ดี.ดี อินฟราสตรัคเจอร์ จำกัด | D38: 45621.937 | E38: - | F38: 15 | G38: - | H38: ยกเลิก | I38: - | J38: กฟอ.กำแพงแสน
A39: PPIM185043D7 | B39: 20003491688 | C39: ที่ว่าการอำเภอกำแพงแสน | D39: 45624.452 | E39: - | F39: 15 | G39: - | H39: ยกเลิก | I39: - | J39: กฟอ.กำแพงแสน
A40: PPIM1850452B | B40: 20026575518 | C40: นาย กาญ บุตรน้ำเพชร์ | D40: 45629.637 | E40: - | F40: 10 | G40: - | H40: ยกเลิก | I40: - | J40: กฟอ.กำแพงแสน
A41: PPIM18504532 | B41: 20003592133 | C41: นาย วิโรจน์ สุขประเสริฐ | D41: 45629.656 | E41: - | F41: 5 | G41: - | H41: ยกเลิก | I41: - | J41: กฟอ.กำแพงแสน
...

Sheet กฟส สามพราน
A2: เลขที่คำขอ | B2: หมายเลข CA | C2: ชื่อผู้ใช้ไฟฟ้า | D2: วันที่ยื่นคำขอ | E2: วันที่ยื่นแก้ไขคำขอ | F2: กำลังการผลิต (kW) | G2: วันที่ชำระเงิน | H2: สถานะคำขอ | J2: พื้นที่ กฟฟ. | L2: รวม | M2: =COUNT(B:B) -> 293 | N2: ราย
A3: PPIM1850003B | B3: 20026098543 | C3: นาย กิติพงษ์ กิจเจริญ | D3: 45307.747 | E3: - | F3: 6.588 | G3: 45372.49 | H3: เชื่อมต่อเรียบร้อยแล้ว | I3: - | J3: กฟอ.สามพราน | L3: รอตรวจสอบคำขอ | M3: =COUNTIF(H:H,"รอตรวจสอบคำขอ") -> 24 | N3: ราย
A4: PPIM185001AA | B4: 20026418170 | C4: นายมณฑล แววับ | D4: 45317.931 | E4: - | F4: 2.562 | G4: - | H4: ยกเลิก | I4: - | J4: กฟอ.สามพราน | L4: ยกเลิก | M4: =COUNTIF(H:H,"ยกเลิก") -> 214 | N4: ราย
A5: PPIM18500394 | B5: 20026643143 | C5: นางสุภัสรา อยู่สุข | D5: 45329.609 | E5: - | F5: 10 | G5: - | H5: ยกเลิก | I5: - | J5: กฟอ.สามพราน | L5: รอผู้ยื่นคำขอส่งเอกสารแก้ไข | M5: =COUNTIF(H:H,"รอผู้ยื่นคำขอส่งเอกสารแก้ไข") -> 0 | N5: ราย
A6: PPIM185007C5 | B6: 20003249820 | C6: นางเตือนจิตต์ แซ่เล้า | D6: 45357.983 | E6: - | F6: 5 | G6: - | H6: ยกเลิก | I6: - | J6: กฟอ.สามพราน | L6: รอชำระเงิน | M6: =COUNTIF(H:H,"รอชำระเงิน") -> 2 | N6: ราย | O6: (รวม รอ หผ / อก / ผจก อนุมัติ ด้วย) | R6: รอ อนุมัติ
A7: PPIM185007C6 | B7: 20003385654 | C7: นางสาวจุฑาทิพย์ ติยะวัชรพงศ์ | D7: 45358.354 | E7: - | F7: 10 | G7: - | H7: ยกเลิก | I7: - | J7: กฟอ.สามพราน | L7: รออนุมัติเชื่อมต่อ/รับพิจารณา | M7: =COUNTIF(H:H,"รออนุมัติเชื่อมต่อ/รับพิจารณา")+COUNTIF(H:H,"รอ หผ. อนุมัติ")+COUNTIF(H:H,"รอ ผจก./อก. อนุมัติ") -> 0 | N7: ราย
A8: PPIM185009F8 | B8: 20026418170 | C8: นายมณฑล แวววับ | D8: 45372.479 | E8: - | F8: 2.562 | G8: 45393.572 | H8: เชื่อมต่อเรียบร้อยแล้ว | I8: - | J8: กฟอ.สามพราน | L8: รอดำเนินการหลังอนุมัติเชื่อมต่อ / รับพิจารณา | M8: =COUNTIF(H:H,"รอดำเนินการหลังอนุมัติเชื่อมต่อ / รับพิจารณา") -> 4 | N8: ราย
A9: PPIM18500EF3 | B9: 20026477902 | C9: น.ส.กนก แจ่มเจริญ | D9: 45409.702 | E9: - | F9: 4 | G9: 45428.435 | H9: เชื่อมต่อเรียบร้อยแล้ว | I9: - | J9: กฟอ.สามพราน | L9: รอแก้ไขเอกสารหลังอนุมัติเชื่อมต่อ / รับพิจารณา | M9: =COUNTIF(H:H,"รอแก้ไขเอกสารหลังอนุมัติเชื่อมต่อ / รับพิจารณา") -> 3 | N9: ราย
A10: PPIM18500FC8 | B10: 20026643143 | C10: นางสุภัสรา อยู่สุข | D10: 45414.786 | E10: - | F10: 10 | G10: 45429.637 | H10: เชื่อมต่อเรียบร้อยแล้ว | I10: - | J10: กฟอ.สามพราน | L10: รออนุมัติเชื่อมต่อ (200 kW ขึ้นไป) | M10: =COUNTIF(H:H,"รออนุมัติเชื่อมต่อ (200 kW ขึ้นไป)") -> 0 | N10: ราย
A11: PPIM18501312 | B11: 20003385654 | C11: นางสาวจุฑาทิพย์ ติยะวัชรพงศ์ | D11: 45433.658 | E11: - | F11: 10 | G11: - | H11: ยกเลิก | I11: - | J11: กฟอ.สามพราน | L11: รอตรวจสอบระบบผลิต | M11: =COUNTIF(H:H,"รอตรวจสอบระบบผลิต") -> 2 | N11: ราย
A12: PPIM185013C9 | B12: 20024958951 | C12: นายชุมพล บุนนาค | D12: 45437.464 | E12: - | F12: 10 | G12: - | H12: ยกเลิก | I12: - | J12: กฟอ.สามพราน | L12: รอทดสอบเชื่อมต่อ | M12: =COUNTIF(H:H,"รอทดสอบเชื่อมต่อ") -> 0 | N12: ราย
A13: PPIM185013FA | B13: 20002913727 | C13: นาง บาหยัน สุพรรณมี | D13: 45439.156 | E13: - | F13: 5 | G13: - | H13: ยกเลิก | I13: - | J13: กฟอ.สามพราน | L13: รออนุมัติแจ้งวันเริ่มเชื่อมต่อ | M13: =COUNTIF(H:H,"รออนุมัติแจ้งวันเริ่มเชื่อมต่อ") -> 0 | N13: ราย
A14: PPIM185011EE | B14: 20003085201 | C14: นายอธิพร กอวัฒนา | D14: 45428.496 | E14: 45443.542 | F14: 6 | G14: 45455.418 | H14: เชื่อมต่อเรียบร้อยแล้ว | I14: - | J14: กฟอ.สามพราน | L14: เชื่อมต่อเรียบร้อยแล้ว | M14: =COUNTIF(H:H,"เชื่อมต่อเรียบร้อยแล้ว") -> 44 | N14: ราย
A15: PPIM185015E5 | B15: 20024958951 | C15: นายชุมพล บุนนาค | D15: 45448.625 | E15: - | F15: 10 | G15: - | H15: ยกเลิก | I15: - | J15: กฟอ.สามพราน
A16: PPIM185010C3 | B16: 20025559002 | C16: นาย พลภัทร วัฒนพงษ์ | D16: 45421.485 | E16: 45448.647 | F16: 2 | G16: 45540.523 | H16: เชื่อมต่อเรียบร้อยแล้ว | I16: - | J16: กฟอ.สามพราน
A17: PPIM18501300 | B17: 20020717757 | C17: วีรวรรณ ภูษณะพงษ์ | D17: 45433.525 | E17: 45448.949 | F17: 15 | G17: 45475.635 | H17: เชื่อมต่อเรียบร้อยแล้ว | I17: - | J17: กฟอ.สามพราน
A18: PPIM185016CD | B18: 20024958951 | C18: นายชุมพล บุนนาค | D18: 45453.489 | E18: - | F18: 10 | G18: - | H18: ยกเลิก | I18: - | J18: กฟอ.สามพราน
A19: PPIM18501744 | B19: 20017983829 | C19: นายพณสรรค์ กิจสวัสดิ์ | D19: 45454.989 | E19: - | F19: 4 | G19: - | H19: ยกเลิก | I19: - | J19: กฟอ.สามพราน
A20: PPIM185017E6 | B20: 20024648425 | C20: นางกฤตพร สังข์รักษา | D20: 45457.59 | E20: - | F20: 5 | G20: - | H20: ยกเลิก | I20: - | J20: กฟอ.สามพราน
A21: PPIM18501A6B | B21: 20024648425 | C21: นางกฤตพร สังข์รักษา | D21: 45469.502 | E21: - | F21: 5 | G21: - | H21: ยกเลิก | I21: - | J21: กฟอ.สามพราน
A22: PPIM1850151F | B22: 20002913727 | C22: นาง บาหยัน สุพรรณมี | D22: 45443.395 | E22: 45471.275 | F22: 5 | G22: 45478.401 | H22: เชื่อมต่อเรียบร้อยแล้ว | I22: - | J22: กฟอ.สามพราน
A23: PPIM18501DDE | B23: 20003385654 | C23: นางสาวจุฑาทิพย์ ติยะวัชรพงศ์ | D23: 45484.453 | E23: - | F23: 10 | G23: - | H23: ยกเลิก | I23: - | J23: กฟอ.สามพราน
A24: PPIM18501E4C | B24: 20019066534 | C24: บริษัท เอสซอม จำกัด | D24: 45485.549 | E24: 45498.581 | F24: 20 | G24: - | H24: ยกเลิก | I24: - | J24: กฟอ.สามพราน
A25: PPIM185021E3 | B25: 20003334716 | C25: ธนาคารออมสิน | D25: 45498.713 | E25: - | F25: 10 | G25: - | H25: ยกเลิก | I25: - | J25: กฟอ.สามพราน
A26: PPIM18502077 | B26: 20003360699 | C26: บริษัท ทองไทย เอ็นจิเนียริ่ง (1992) จำกัด | D26: 45493.524 | E26: 45504.439 | F26: 20 | G26: 45531.538 | H26: เชื่อมต่อเรียบร้อยแล้ว | I26: - | J26: กฟอ.สามพราน
A27: PPIM18501D3F | B27: 20003124084 | C27: นาง รุจิรัตน์ ซิ้มเจริญ | D27: 45482.4 | E27: 45504.603 | F27: 5 | G27: - | H27: ยกเลิก | I27: - | J27: กฟอ.สามพราน
A28: PPIM18501D0C | B28: 20027681616 | C28: นายเฉลิมพร บุญขุนยัง | D28: 45481.592 | E28: 45504.611 | F28: 5 | G28: - | H28: ยกเลิก | I28: - | J28: กฟอ.สามพราน
A29: PPIM1850232E | B29: 20003385654 | C29: นางสาวจุฑาทิพย์ ติยะวัชรพงศ์ | D29: 45505.58 | E29: - | F29: 10 | G29: - | H29: ยกเลิก | I29: - | J29: กฟอ.สามพราน
A30: PPIM18502484 | B30: 20027832751 | C30: นายไพฑูลย์ หงษา | D30: 45512.773 | E30: - | F30: 3 | G30: - | H30: ยกเลิก | I30: - | J30: กฟอ.สามพราน
A31: PPIM18502512 | B31: 20026866591 | C31: นางสาวชมพูนุท ทองม่วง | D31: 45514.997 | E31: - | F31: 10 | G31: - | H31: ยกเลิก | I31: - | J31: กฟอ.สามพราน
A32: PPIM1850260A | B32: 20020971333 | C32: บุศรา กรรณรัตนสูตร | D32: 45518.835 | E32: - | F32: 10 | G32: - | H32: ยกเลิก | I32: - | J32: กฟอ.สามพราน
A33: PPIM1850271D | B33: 20027337292 | C33: กิตติพงษ์ เชาวนวิรัตน์ | D33: 45523.452 | E33: - | F33: 15 | G33: - | H33: เชื่อมต่อเรียบร้อยแล้ว | I33: - | J33: กฟอ.สามพราน
A34: PPIM18501CE0 | B34: 20025864204 | C34: นาย กมลพัฒน์ จิระพันธ์ทิพย์ | D34: 45481.387 | E34: 45526.368 | F34: 3 | G34: 45539.645 | H34: เชื่อมต่อเรียบร้อยแล้ว | I34: - | J34: กฟอ.สามพราน
A35: PPIM18502814 | B35: 20020184213 | C35: นายพลิศวร์ รัตนสวัสดิ์ | D35: 45525.758 | E35: 45530.369 | F35: 20 | G35: 45530.649 | H35: เชื่อมต่อเรียบร้อยแล้ว | I35: - | J35: กฟอ.สามพราน
A36: PPIM185028DB | B36: 20003043484 | C36: นางจุฑารัตน์ เสนาคำ | D36: 45528.603 | E36: 45530.61 | F36: 10 | G36: 45537.588 | H36: เชื่อมต่อเรียบร้อยแล้ว | I36: - | J36: กฟอ.สามพราน
A37: PPIM18502962 | B37: 20026287827 | C37: สมฤดี เนื้อนิ่ม | D37: 45530.895 | E37: - | F37: 20 | G37: - | H37: ยกเลิก | I37: - | J37: กฟอ.สามพราน
A38: PPIM185029CF | B38: 20026287827 | C38: บริษัท ตลาดสดฟาร์มสมบูรณ์ จำกัด | D38: 45532.251 | E38: - | F38: 20 | G38: - | H38: ยกเลิก | I38: - | J38: กฟอ.สามพราน
A39: PPIM18502A79 | B39: 20020914714 | C39: นาง ศิริพรรณ จันธนะตระกูล | D39: 45533.7 | E39: - | F39: 5 | G39: - | H39: ยกเลิก | I39: - | J39: กฟอ.สามพราน
A40: PPIM18502670 | B40: 20026866591 | C40: นางสาวชมพูนุท ทองม่วง | D40: 45519.957 | E40: 45533.907 | F40: 10 | G40: - | H40: ยกเลิก | I40: - | J40: กฟอ.สามพราน
A41: PPIM18502AF0 | B41: 20003025330 | C41: บริษัท.โตฟู โออิชิ ฟู้ดส์โปรดัคท์ จำกัด | D41: 45535.496 | E41: - | F41: 20 | G41: - | H41: ยกเลิก | I41: - | J41: กฟอ.สามพราน
...

Sheet กฟส บางเลน
A2: เลขที่คำขอ | B2: หมายเลข CA | C2: ชื่อผู้ใช้ไฟฟ้า | D2: วันที่ยื่นคำขอ | E2: วันที่ยื่นแก้ไขคำขอ | F2: กำลังการผลิต (kW) | G2: วันที่ชำระเงิน | H2: สถานะคำขอ | J2: พื้นที่ กฟฟ. | L2: รวม | M2: =COUNT(B:B) -> 52 | N2: ราย
A3: PPIM18500140 | B3: 20023475316 | C3: นางสาว พูลสวัสดิ์ สิงห์ดง | D3: 45315.666 | E3: - | F3: 5 | G3: - | H3: ยกเลิก | I3: - | J3: กฟต.บางหลวง | L3: รอตรวจสอบคำขอ | M3: =COUNTIF(H:H,"รอตรวจสอบคำขอ") -> 14 | N3: ราย
A4: PPIM18500A1F | B4: 20000673517 | C4: นายธวัชชัย แก้วฉลวย | D4: 45373.119 | E4: - | F4: 5 | G4: - | H4: ยกเลิก | I4: - | J4: กฟอ.บางเลน | L4: ยกเลิก | M4: =COUNTIF(H:H,"ยกเลิก") -> 8 | N4: ราย
A5: PPIM18500BE0 | B5: 20003096662 | C5: นายศรีทัย แก้วชมเชย | D5: 45384.762 | E5: - | F5: 5 | G5: - | H5: ยกเลิก | I5: - | J5: กฟต.บางหลวง | L5: รอผู้ยื่นคำขอส่งเอกสารแก้ไข | M5: =COUNTIF(H:H,"รอผู้ยื่นคำขอส่งเอกสารแก้ไข") -> 0 | N5: ราย
A6: PPIM18500BE1 | B6: 20003096662 | C6: นายศรีทัย แก้วชมเชย | D6: 45384.779 | E6: 45489.623 | F6: 5 | G6: 45650.592 | H6: รอดำเนินการหลังอนุมัติเชื่อมต่อ / รับพิจารณา | I6: - | J6: กฟต.บางหลวง | L6: รอชำระเงิน | M6: =COUNTIF(H:H,"รอชำระเงิน") -> 1 | N6: ราย | O6: (รวม รอ หผ / อก / ผจก อนุมัติ ด้วย)
A7: PPIM18500E13 | B7: 20003301273 | C7: นายศิริพงศ์ รักษาพงศ์ | D7: 45404.676 | E7: 45490.658 | F7: 10 | G7: 45575.604 | H7: รอตรวจสอบระบบผลิต | I7: - | J7: กฟต.บางหลวง | L7: รออนุมัติเชื่อมต่อ/รับพิจารณา | M7: =COUNTIF(H:H,"รออนุมัติเชื่อมต่อ/รับพิจารณา")+COUNTIF(H:H,"รอ หผ. อนุมัติ")+COUNTIF(H:H,"รอ ผจก./อก. อนุมัติ") -> 13 | N7: ราย
A8: PPIM18501761 | B8: 20026714597 | C8: นางสาว อรยุภา ทิพยานนท์ | D8: 45456.447 | E8: 45491.526 | F8: 5 | G8: 45572.488 | H8: เชื่อมต่อเรียบร้อยแล้ว | I8: - | J8: กฟอ.บางเลน | L8: รอดำเนินการหลังอนุมัติเชื่อมต่อ / รับพิจารณา | M8: =COUNTIF(H:H,"รอดำเนินการหลังอนุมัติเชื่อมต่อ / รับพิจารณา") -> 3 | N8: ราย
A9: PPIM185020DD | B9: 20003204576 | C9: นายสมศักดิ์ สมกุล | D9: 45495.936 | E9: - | F9: 10 | G9: 45590.642 | H9: รอดำเนินการหลังอนุมัติเชื่อมต่อ / รับพิจารณา | I9: - | J9: กฟอ.บางเลน | L9: รอแก้ไขเอกสารหลังอนุมัติเชื่อมต่อ / รับพิจารณา | M9: =COUNTIF(H:H,"รอแก้ไขเอกสารหลังอนุมัติเชื่อมต่อ / รับพิจารณา") -> 0 | N9: ราย
A10: PPIM185021CB | B10: 20003535101 | C10: ธนาคารออมสิน | D10: 45498.642 | E10: 45513.497 | F10: 10 | G10: 45567.431 | H10: เชื่อมต่อเรียบร้อยแล้ว | I10: - | J10: กฟอ.บางเลน | L10: รออนุมัติเชื่อมต่อ (200 kW ขึ้นไป) | M10: =COUNTIF(H:H,"รออนุมัติเชื่อมต่อ (200 kW ขึ้นไป)") -> 0 | N10: ราย
A11: PPIM1850281D | B11: 20018544538 | C11: นางปุณญพร เทียมสุชาติ | D11: 45525.961 | E11: - | F11: 10 | G11: - | H11: ยกเลิก | I11: - | J11: กฟอ.บางเลน | L11: รอตรวจสอบระบบผลิต | M11: =COUNTIF(H:H,"รอตรวจสอบระบบผลิต") -> 8 | N11: ราย
A12: PPIM1850295C | B12: 20022087542 | C12: นายชัยนรินท์ ธนาสถิตย์วงษ์ | D12: 45530.859 | E12: - | F12: 12 | G12: 45593.61 | H12: รอตรวจสอบระบบผลิต | I12: - | J12: กฟอ.บางเลน | L12: รอทดสอบเชื่อมต่อ | M12: =COUNTIF(H:H,"รอทดสอบเชื่อมต่อ") -> 0 | N12: ราย
A13: PPIM1850295D | B13: 20023247478 | C13: นายชัยนรินท์ ธนาสถิตย์วงษ์ | D13: 45530.865 | E13: - | F13: 20 | G13: 45593.61 | H13: รอตรวจสอบระบบผลิต | I13: - | J13: กฟอ.บางเลน | L13: รออนุมัติแจ้งวันเริ่มเชื่อมต่อ | M13: =COUNTIF(H:H,"รออนุมัติแจ้งวันเริ่มเชื่อมต่อ") -> 0 | N13: ราย
A14: PPIM18502F6B | B14: 20024250642 | C14: เพชรพลอย อัครวัฒนวาณิช | D14: 45552.014 | E14: - | F14: 5 | G14: 45576.565 | H14: เชื่อมต่อเรียบร้อยแล้ว | I14: - | J14: กฟอ.บางเลน | L14: เชื่อมต่อเรียบร้อยแล้ว | M14: =COUNTIF(H:H,"เชื่อมต่อเรียบร้อยแล้ว") -> 5 | N14: ราย
A15: PPIM1850278E | B15: 20026058038 | C15: นายจีระศักดิ์ น้อยพันธุ์ | D15: 45524.503 | E15: 45552.73 | F15: 10 | G15: 45573.46 | H15: รอดำเนินการหลังอนุมัติเชื่อมต่อ / รับพิจารณา | I15: - | J15: กฟต.บางหลวง
A16: PPIM18503E93 | B16: 20026652091 | C16: บริษัท ทรู มูฟ เอช ยูนิเวอร์แซล คอมมิวนิเคชั่น จำกัด | D16: 45604.614 | E16: - | F16: 12 | G16: 45670.581 | H16: เชื่อมต่อเรียบร้อยแล้ว | I16: - | J16: กฟอ.บางเลน
A17: PPIM1850401E | B17: 0 | C17: โรงเรียนวัดลำพญา | D17: 45610.415 | E17: - | F17: 10 | G17: - | H17: ยกเลิก | I17: - | J17: กฟอ.บางเลน
A18: PPIM18504022 | B18: 0 | C18: โรงเรียนบางปลา (เมธีจุลารักษ์) | D18: 45610.424 | E18: - | F18: 10 | G18: - | H18: ยกเลิก | I18: - | J18: กฟอ.บางเลน
A19: PPIM185044C0 | B19: 20003475221 | C19: โรงพยาบาลส่งเสริมสุขภาพตำบลบ้านเกาะแรด | D19: 45628.456 | E19: - | F19: 10 | G19: 45673.537 | H19: เชื่อมต่อเรียบร้อยแล้ว | I19: - | J19: กฟอ.บางเลน
A20: PPIM1850489C | B20: 20019125468 | C20: บริษัท ซิสเต็ม 3 จำกัด | D20: 45645.449 | E20: - | F20: 15 | G20: - | H20: รออนุมัติเชื่อมต่อ/รับพิจารณา | I20: อฝ./ผจก. | J20: กฟต.บางหลวง
A21: PPIM1950005B | B21: 20019679001 | C21: นายสุวิชชาญ เนตรนาค | D21: 45660.633 | E21: - | F21: 12 | G21: - | H21: ยกเลิก | I21: - | J21: กฟอ.บางเลน
A22: PPIM1850339E | B22: 20003583700 | C22: นาย ณรงค์ศักดิ์ ค้าธัญญมงคล | D22: 45565.695 | E22: 45668.484 | F22: 10 | G22: - | H22: รออนุมัติเชื่อมต่อ/รับพิจารณา | I22: อฝ./ผจก. | J22: กฟต.บางหลวง
A23: PPIM18503BB3 | B23: 20026021180 | C23: นางสุรัตน์ ไชยพันธุ์ | D23: 45594.645 | E23: 45669.481 | F23: 5 | G23: - | H23: ยกเลิก | I23: - | J23: กฟต.บางหลวง
A24: PPIM1850474A | B24: 20003471273 | C24: ดวงเนตร ชดช้อย | D24: 45639.661 | E24: 45670.498 | F24: 5 | G24: - | H24: รออนุมัติเชื่อมต่อ/รับพิจารณา | I24: อฝ./ผจก. | J24: กฟต.บางหลวง
A25: PPIM1950006B | B25: 20026053865 | C25: นางสาว ฎารารัตน์ กลิ่นจันทร์คลาย | D25: 45661.38 | E25: 45674.463 | F25: 15 | G25: - | H25: รออนุมัติเชื่อมต่อ/รับพิจารณา | I25: อฝ./ผจก. | J25: กฟอ.บางเลน
A26: PPIM19500344 | B26: 20026373472 | C26: นางสาวดวงใจ ศักดิ์ศรี | D26: 45672.658 | E26: 45674.658 | F26: 3 | G26: - | H26: รออนุมัติเชื่อมต่อ/รับพิจารณา | I26: อฝ./ผจก. | J26: กฟอ.บางเลน
A27: PPIM195005DA | B27: 20016470166 | C27: นาง ธนวันต์ ชื่นใจดี | D27: 45681.567 | E27: 45691.449 | F27: 3 | G27: - | H27: รออนุมัติเชื่อมต่อ/รับพิจารณา | I27: อฝ./ผจก. | J27: กฟอ.บางเลน
A28: PPIM1950097E | B28: 20003120573 | C28: นายสำเนียง มีถาวร | D28: 45696.679 | E28: - | F28: 5 | G28: - | H28: รออนุมัติเชื่อมต่อ/รับพิจารณา | I28: อฝ./ผจก. | J28: กฟอ.บางเลน
A29: PPIM195011E1 | B29: 20027944804 | C29: นายเปม ราคา | D29: 45727.675 | E29: - | F29: 5 | G29: - | H29: รออนุมัติเชื่อมต่อ/รับพิจารณา | I29: อฝ./ผจก. | J29: กฟอ.บางเลน
A30: PPIM195011F2 | B30: 20020169405 | C30: นายอนุชาติ มกรสิริพัชร์ | D30: 45727.719 | E30: - | F30: 3 | G30: - | H30: รอชำระเงิน | I30: - | J30: กฟอ.บางเลน
A31: PPIM19500BCF | B31: 20026021180 | C31: นางสุรัตน์ ไชยพันธุ์ | D31: 45706.674 | E31: 45769.685 | F31: 5 | G31: - | H31: รออนุมัติเชื่อมต่อ/รับพิจารณา | I31: อฝ./ผจก. | J31: กฟต.บางหลวง
A32: PPIM1950214E | B32: 20003308803 | C32: นาย สมศักดิ์ พรหมสมบัติ | D32: 45783.674 | E32: - | F32: 10 | G32: 45917.542 | H32: รอตรวจสอบระบบผลิต | I32: - | J32: กฟอ.บางเลน
A33: PPIM19502514 | B33: 20003350317 | C33: นาย บุญชัย นันทปรีชาชาญ | D33: 45798.527 | E33: - | F33: 5 | G33: - | H33: รออนุมัติเชื่อมต่อ/รับพิจารณา | I33: หผ. | J33: กฟอ.บางเลน
A34: PPIM19502973 | B34: 20026723820 | C34: นางสาวเนตรนภา วิลัยสิทธิ์ | D34: 45810.713 | E34: - | F34: 5 | G34: - | H34: รออนุมัติเชื่อมต่อ/รับพิจารณา | I34: หผ. | J34: กฟอ.บางเลน
A35: PPIM195031C8 | B35: 20019803214 | C35: บริษัท แอ็ดซายน์ เทรด | D35: 45838.693 | E35: - | F35: 10 | G35: - | H35: รอตรวจสอบคำขอ | I35: - | J35: กฟอ.บางเลน
A36: PPIM195031CD | B36: 20019803207 | C36: บริษัท อีวัน อโกรเทค จำกัด | D36: 45838.703 | E36: - | F36: 5 | G36: - | H36: รออนุมัติเชื่อมต่อ/รับพิจารณา | I36: หผ. | J36: กฟอ.บางเลน
A37: PPIM1950352A | B37: 20025533023 | C37: บริษัท เอวัน ออยล์ จำกัด | D37: 45850.666 | E37: - | F37: 20 | G37: 45922.597 | H37: รอตรวจสอบระบบผลิต | I37: - | J37: กฟอ.บางเลน
A38: PPIM1950414A | B38: 20022508595 | C38: นางสาวยุวดี เลิศวิริยะศักดิ์ | D38: 45894.508 | E38: - | F38: 5 | G38: - | H38: รอตรวจสอบคำขอ | I38: - | J38: กฟต.บางหลวง
A39: PPIM19504447 | B39: 20003567117 | C39: นางสมคิด จิตรเจือ | D39: 45904.665 | E39: 45909.439 | F39: 3.5 | G39: 45926.494 | H39: รอตรวจสอบระบบผลิต | I39: - | J39: กฟอ.บางเลน
A40: PPIM19503C94 | B40: 20021438211 | C40: น.ส.รุ่งนภา แก้วศรีพันธุ์ | D40: 45877.424 | E40: 45909.629 | F40: 10 | G40: 45982.572 | H40: รอตรวจสอบระบบผลิต | I40: - | J40: กฟอ.บางเลน
A41: PPIM195045B4 | B41: 20003480452 | C41: โรงพยาบาลส่งเสริมสุขภาพตำบล ตำบลบางภาษี | D41: 45910.389 | E41: - | F41: 15 | G41: - | H41: รออนุมัติเชื่อมต่อ/รับพิจารณา | I41: หผ. | J41: กฟอ.บางเลน
...

Sheet กฟส พุทธมณฑล
